Workbook

Sheet Registration
B1: 2017 Relay Race
A2: List | B2: Bib # | C2: Division | D2: Name
A3: 1 | B3: 1 | C3: 1 | D3: THAT'S FINE TRACK CLUB
A4: 2 | B4: 2 | C4: 1 | D4: Lancer Punch
A5: 3 | B5: 3 | C5: 1 | D5: OH Trail Blazers
A6: 4 | B6: 4 | C6: 1 | D6: Rubicon Rumm Runners
A7: 5 | B7: 5 | C7: 1 | D7: Moraga Distance Project
A8: 6 | B8: 6 | C8: 1 | D8: Chiclosos
A9: 7 | B9: 7 | C9: 1 | D9: West Valley Track Club B
A10: 8 | B10: 8 | C10: 2 | D10: Run Like You Stole it | E10: DNS
A11: 9 | B11: 9 | C11: 2 | D11: West Valley TC Masters Men
A12: 10 | B12: 10 | C12: 3 | D12: Original A Team
A13: 11 | B13: 11 | C13: 3 | D13: Harey Tortugas
A14: 12 | B14: 12 | C14: 1 | D14: Team Carpe Gluteus
A15: 13 | B15: 13 | C15: 4 | D15: LMJS 60-70 Men
A16: 14 | B16: 14 | C16: 5 | D16: Fresno High School - Girls
A17: 15 | B17: 15 | C17: 6 | D17: The Sports Thing
A18: 16 | B18: 16 | C18: 6 | D18: McNair High School
A19: 17 | B19: 17 | C19: 6 | D19: Fresno High School - Boys
A20: 18 | B20: 18 | C20: 6 | D20: McFarland Track Club 1
A21: 19 | B21: 19 | C21: 6 | D21: McFarland Track Club 2
A22: 20 | B22: 20 | C22: 6 | D22: South Tahoe High School
... A24: 22 | B24: 22 | C24: 7 | D24: Brown Runners - UPS 1
A25: 23 | B25: 23 | C25: 7 | D25: Always Promise Never Deliver | E25: DNF
A26: 24 | B26: 24 | C26: 7 | D26: Parlimnet of Owls
A27: 25 | B27: 25 | C27: 7 | D27: Over Promise Under Deliver
A28: 26 | B28: 26 | C28: 7 | D28: Browns Clowns - UPS 2
A29: 27 | B29: 27 | C29: 7 | D29: The KP Wandering Landlubbers
A30: 28 | B30: 28 | C30: 7 | D30: The Last Will be First
A31: 29 | B31: 29 | C31: 8 | D31: Shark Week
A32: 30 | B32: 30 | C32: 8 | D32: Fly The Friendly Skies
A33: 31 | B33: 31 | C33: 8 | D33: Jurassic Park
A34: 32 | B34: 32 | C34: 8 | D34: Summer of Love
A35: 33 | B35: 33 | C35: 8 | D35: Jock and Jills
A36: 34 | B36: 34 | C36: 8 | D36: Hot Links
A37: 35 | B37: 35 | C37: 8 | D37: No Passing | E37: DNS
A38: 36 | B38: 36 | C38: 8 | D38: Norcal Sheepdogs
A39: 37 | B39: 37 | C39: 8 | D39: Last Hoorah
A40: 38 | B40: 38 | C40: 8 | D40: We Trained at Sea Level
A41: 39 | B41: 39 | C41: 8 | D41: South Coast Roadrunners
...

Sheet Div Sorted Results
A1: Sorted Results
B2: 2017 Tahoe Relay
A4: Overall Place | B4: Bib # | C4: Total Time | D4: Div | E4: Div Place | F4: Pace
A5: 1 | B5: 1 | C5: 0.28646991 | D5: =VLOOKUP(B5,Registration!$B$3:$C$77,2,FALSE) -> 1 | E5: 1 | F5: =C5/72 -> 0.0039787487
A6: 2 | B6: 68 | C6: 0.28778935 | D6: =VLOOKUP(B6,Registration!$B$3:$C$77,2,FALSE) -> 1 | E6: 2 | F6: =C6/72 -> 0.0039970743
A7: 3 | B7: 7 | C7: 0.30519676 | D7: =VLOOKUP(B7,Registration!$B$3:$C$77,2,FALSE) -> 1 | E7: 3 | F7: =C7/72 -> 0.0042388439
A8: 4 | B8: 5 | C8: 0.31356481 | D8: =VLOOKUP(B8,Registration!$B$3:$C$77,2,FALSE) -> 1 | E8: 4 | F8: =C8/72 -> 0.0043550669
A9: 5 | B9: 9 | C9: 0.31668981 | D9: =VLOOKUP(B9,Registration!$B$3:$C$77,2,FALSE) -> 2 | E9: 1 | F9: =C9/72 -> 0.0043984697
A10: 6 | B10: 2 | C10: 0.31797454 | D10: =VLOOKUP(B10,Registration!$B$3:$C$77,2,FALSE) -> 1 | E10: 5 | F10: =C10/72 -> 0.004416313
A11: 7 | B11: 18 | C11: 0.33782407 | D11: =VLOOKUP(B11,Registration!$B$3:$C$77,2,FALSE) -> 6 | E11: 1 | F11: =C11/72 -> 0.004692001
A12: 8 | B12: 47 | C12: 0.33837963 | D12: =VLOOKUP(B12,Registration!$B$3:$C$77,2,FALSE) -> 8 | E12: 1 | F12: =C12/72 -> 0.0046997171
A13: 9 | B13: 43 | C13: 0.35443287 | D13: =VLOOKUP(B13,Registration!$B$3:$C$77,2,FALSE) -> 8 | E13: 2 | F13: =C13/72 -> 0.0049226788
A14: 10 | B14: 59 | C14: 0.35488426 | D14: =VLOOKUP(B14,Registration!$B$3:$C$77,2,FALSE) -> 10 | E14: 1 | F14: =C14/72 -> 0.004928948
A15: 11 | B15: 17 | C15: 0.35825231 | D15: =VLOOKUP(B15,Registration!$B$3:$C$77,2,FALSE) -> 6 | E15: 2 | F15: =C15/72 -> 0.0049757266
A16: 12 | B16: 58 | C16: 0.35827546 | D16: =VLOOKUP(B16,Registration!$B$3:$C$77,2,FALSE) -> 10 | E16: 2 | F16: =C16/72 -> 0.0049760481
... A67: 63 | B67: 26 | C67: 0.55287037 | D67: =VLOOKUP(B67,Registration!$B$3:$C$77,2,FALSE) -> 7 | E67: 8 | F67: =C67/72 -> 0.0076787551
A69: 23 | C69: DNF
A70: 66 | C70: DNF
A71: 67 | C71: DNF

Sheet Leg 1
A1: Leg 1 | B1: 2017 Tahoe Relay
F2: 8.6 Miles
A3: Place | B3: Bib # | C3: Leg Time | D3: Div | E3: Div Place | F3: Pace
A4: 1 | B4: 5 | C4: 0.033784722 | D4: =VLOOKUP(B4,Registration!$B$3:$C$77,2,FALSE) -> 1 | E4: 1 | F4: =C4/8.6 -> 0.0039284561
A5: 2 | B5: 68 | C5: 0.034247685 | D5: =VLOOKUP(B5,Registration!$B$3:$C$77,2,FALSE) -> 1 | E5: 2 | F5: =C5/8.6 -> 0.003982289
A6: 3 | B6: 47 | C6: 0.035798611 | D6: =VLOOKUP(B6,Registration!$B$3:$C$77,2,FALSE) -> 8 | E6: 1 | F6: =C6/8.6 -> 0.0041626292
A7: 4 | B7: 7 | C7: 0.036064815 | D7: =VLOOKUP(B7,Registration!$B$3:$C$77,2,FALSE) -> 1 | E7: 3 | F7: =C7/8.6 -> 0.0041935831
A8: 5 | B8: 9 | C8: 0.03625 | D8: =VLOOKUP(B8,Registration!$B$3:$C$77,2,FALSE) -> 2 | E8: 1 | F8: =C8/8.6 -> 0.0042151163
A9: 6 | B9: 1 | C9: 0.037789352 | D9: =VLOOKUP(B9,Registration!$B$3:$C$77,2,FALSE) -> 1 | E9: 4 | F9: =C9/8.6 -> 0.0043941107
A10: 7 | B10: 18 | C10: 0.03900463 | D10: =VLOOKUP(B10,Registration!$B$3:$C$77,2,FALSE) -> 6 | E10: 1 | F10: =C10/8.6 -> 0.004535422
A11: 8 | B11: 43 | C11: 0.039537037 | D11: =VLOOKUP(B11,Registration!$B$3:$C$77,2,FALSE) -> 8 | E11: 2 | F11: =C11/8.6 -> 0.0045973299
A12: 9 | B12: 19 | C12: 0.039594907 | D12: =VLOOKUP(B12,Registration!$B$3:$C$77,2,FALSE) -> 6 | E12: 2 | F12: =C12/8.6 -> 0.004604059
A13: 10 | B13: 56 | C13: 0.039837963 | D13: =VLOOKUP(B13,Registration!$B$3:$C$77,2,FALSE) -> 9 | E13: 1 | F13: =C13/8.6 -> 0.0046323213
A14: 11 | B14: 4 | C14: 0.040960648 | D14: =VLOOKUP(B14,Registration!$B$3:$C$77,2,FALSE) -> 1 | E14: 5 | F14: =C14/8.6 -> 0.0047628661
A15: 12 | B15: 2 | C15: 0.04130787 | D15: =VLOOKUP(B15,Registration!$B$3:$C$77,2,FALSE) -> 1 | E15: 6 | F15: =C15/8.6 -> 0.0048032407
... A64: 61 | B64: 26 | C64: 0.070914352 | D64: =VLOOKUP(B64,Registration!$B$3:$C$77,2,FALSE) -> 7 | E64: 8 | F64: =C64/8.6 -> 0.0082458549
A65: 62
A66: 63
A67: 64
A68: 65
A69: 66
A70: 67
C72: We missed timing on leg 1 for bibs 41 and 59
C73: Bibs 55 and 67 started at 5am
C74: Bib 66 started at 6am

Sheet leg 2
A1: Leg 2 | B1: 2017 Tahoe Relay | F1: Leg 2 | G1: Lake Tahoe Relay
L2: 13.1 Miles
A3: Place | B3: Bib # | C3: Total Time | D3: Leg Time | E3: Div | F3: Place | G3: Bib # | H3: Total Time | I3: Leg Time | J3: Div | K3: Div Place | L3: Pace
A4: 1 | B4: 68 | C4: 0.088298611 | D4: ='leg 2'!C4-'Leg 1'!C4 -> 0.054513889 | E4: =VLOOKUP(B4,Registration!$B$3:$C$77,2,FALSE) -> 1 | F4: 1 | G4: 68 | H4: 0.088298611 | I4: =H4-'Leg 1'!C5 -> 0.054050926 | J4: =VLOOKUP(G4,[1]Registration!$B$3:$C$77,2,FALSE) -> 1 | K4: 1 | L4: =I4/13.1 -> 0.0041260249
A5: 2 | B5: 1 | C5: 0.091122685 | D5: ='leg 2'!C5-'Leg 1'!C5 -> 0.056875 | E5: =VLOOKUP(B5,Registration!$B$3:$C$77,2,FALSE) -> 1 | F5: 2 | G5: 1 | H5: 0.091122685 | I5: =H5-'Leg 1'!C9 -> 0.053333333 | J5: =VLOOKUP(G5,[1]Registration!$B$3:$C$77,2,FALSE) -> 1 | K5: 2 | L5: =I5/13.1 -> 0.0040712468
A6: 3 | B6: 7 | C6: 0.093796296 | D6: ='leg 2'!C6-'Leg 1'!C6 -> 0.057997685 | E6: =VLOOKUP(B6,Registration!$B$3:$C$77,2,FALSE) -> 1 | F6: 3 | G6: 7 | H6: 0.093796296 | I6: =H6-'Leg 1'!C7 -> 0.057731481 | J6: =VLOOKUP(G6,[1]Registration!$B$3:$C$77,2,FALSE) -> 1 | K6: 3 | L6: =I6/13.1 -> 0.0044069833
A7: 4 | B7: 5 | C7: 0.094224537 | D7: ='leg 2'!C7-'Leg 1'!C7 -> 0.058159722 | E7: =VLOOKUP(B7,Registration!$B$3:$C$77,2,FALSE) -> 1 | F7: 4 | G7: 5 | H7: 0.094224537 | I7: =H7-'Leg 1'!C4 -> 0.060439815 | J7: =VLOOKUP(G7,[1]Registration!$B$3:$C$77,2,FALSE) -> 1 | K7: 4 | L7: =I7/13.1 -> 0.0046137263
A8: 5 | B8: 2 | C8: 0.095775463 | D8: ='leg 2'!C8-'Leg 1'!C8 -> 0.059525463 | E8: =VLOOKUP(B8,Registration!$B$3:$C$77,2,FALSE) -> 1 | F8: 5 | G8: 2 | H8: 0.095775463 | I8: =H8-'Leg 1'!C15 -> 0.054467593 | J8: =VLOOKUP(G8,[1]Registration!$B$3:$C$77,2,FALSE) -> 1 | K8: 5 | L8: =I8/13.1 -> 0.0041578315
A9: 6 | B9: 9 | C9: 0.096018519 | D9: ='leg 2'!C9-'Leg 1'!C9 -> 0.058229167 | E9: =VLOOKUP(B9,Registration!$B$3:$C$77,2,FALSE) -> 2 | F9: 6 | G9: 9 | H9: 0.096018519 | I9: =H9-'Leg 1'!C8 -> 0.059768519 | J9: =VLOOKUP(G9,[1]Registration!$B$3:$C$77,2,FALSE) -> 2 | K9: 1 | L9: =I9/13.1 -> 0.0045624823
A10: 7 | B10: 47 | C10: 0.097210648 | D10: ='leg 2'!C10-'Leg 1'!C10 -> 0.058206019 | E10: =VLOOKUP(B10,Registration!$B$3:$C$77,2,FALSE) -> 8 | F10: 7 | G10: 47 | H10: 0.097210648 | I10: =H10-'Leg 1'!C6 -> 0.061412037 | J10: =VLOOKUP(G10,[1]Registration!$B$3:$C$77,2,FALSE) -> 8 | K10: 1 | L10: =I10/13.1 -> 0.0046879418
A11: 8 | B11: 18 | C11: 0.098449074 | D11: ='leg 2'!C11-'Leg 1'!C11 -> 0.058912037 | E11: =VLOOKUP(B11,Registration!$B$3:$C$77,2,FALSE) -> 6 | F11: 8 | G11: 18 | H11: 0.098449074 | I11: =H11-'Leg 1'!C10 -> 0.059444444 | J11: =VLOOKUP(G11,[1]Registration!$B$3:$C$77,2,FALSE) -> 6 | K11: 1 | L11: =I11/13.1 -> 0.0045377439
A12: 9 | B12: 6 | C12: 0.10118056 | D12: ='leg 2'!C12-'Leg 1'!C12 -> 0.061585648 | E12: =VLOOKUP(B12,Registration!$B$3:$C$77,2,FALSE) -> 1 | F12: 9 | G12: 6 | H12: 0.10118056 | I12: =H12-'Leg 1'!C10 -> 0.062175926 | J12: =VLOOKUP(G12,[1]Registration!$B$3:$C$77,2,FALSE) -> 1 | K12: 6 | L12: =I12/13.1 -> 0.0047462539
A13: 10 | B13: 55 | C13: 0.10255787 | D13: ='leg 2'!C13-'Leg 1'!C13 -> 0.062719907 | E13: =VLOOKUP(B13,Registration!$B$3:$C$77,2,FALSE) -> 9 | F13: 10 | G13: 55 | H13: 0.10255787 | J13: =VLOOKUP(G13,[1]Registration!$B$3:$C$77,2,FALSE) -> 9 | K13: 1 | L13: =I13/13.1 -> 0
A14: 11 | B14: 43 | C14: 0.10350694 | D14: ='leg 2'!C14-'Leg 1'!C14 -> 0.062546296 | E14: =VLOOKUP(B14,Registration!$B$3:$C$77,2,FALSE) -> 8 | F14: 11 | G14: 43 | H14: 0.10350694 | I14: =H14-'Leg 1'!C11 -> 0.063969907 | J14: =VLOOKUP(G14,[1]Registration!$B$3:$C$77,2,FALSE) -> 8 | K14: 2 | L14: =I14/13.1 -> 0.004883199
A15: 12 | B15: 45 | C15: 0.10619213 | D15: ='leg 2'!C15-'Leg 1'!C15 -> 0.064884259 | E15: =VLOOKUP(B15,Registration!$B$3:$C$77,2,FALSE) -> 8 | F15: 12 | G15: 45 | H15: 0.10619213 | I15: =H15-'Leg 1'!C19 -> 0.061608796 | J15: =VLOOKUP(G15,[1]Registration!$B$3:$C$77,2,FALSE) -> 8 | K15: 3 | L15: =I15/13.1 -> 0.0047029615
A16: 13 | B16: 59 | C16: 0.10686343 | D16: ='leg 2'!C16-'Leg 1'!C16 -> 0.065486111 | E16: =VLOOKUP(B16,Registration!$B$3:$C$77,2,FALSE) -> 10 | F16: 13 | G16: 59 | H16: 0.10686343 | J16: =VLOOKUP(G16,[1]Registration!$B$3:$C$77,2,FALSE) -> 10 | K16: 1 | L16: =I16/13.1 -> 0
A17: 14 | B17: 4 | C17: 0.10895833 | D17: ='leg 2'!C17-'Leg 1'!C17 -> 0.0653125 | E17: =VLOOKUP(B17,Registration!$B$3:$C$77,2,FALSE) -> 1 | F17: 14 | G17: 4 | H17: 0.10895833 | I17: =H17-'Leg 1'!C14 -> 0.067997685 | J17: =VLOOKUP(G17,[1]Registration!$B$3:$C$77,2,FALSE) -> 1 | K17: 7 | L17: =I17/13.1 -> 0.005190663
A18: 15 | B18: 65 | C18: 0.11111111 | D18: ='leg 2'!C18-'Leg 1'!C18 -> 0.066956019 | E18: =VLOOKUP(B18,Registration!$B$3:$C$77,2,FALSE) -> 10 | F18: 15 | G18: 65 | H18: 0.11111111 | I18: =H18-'Leg 1'!C17 -> 0.067465278 | J18: =VLOOKUP(G18,[1]Registration!$B$3:$C$77,2,FALSE) -> 10 | K18: 2 | L18: =I18/13.1 -> 0.0051500212
A19: 16 | B19: 63 | C19: 0.11116898 | D19: ='leg 2'!C19-'Leg 1'!C19 -> 0.066585648 | E19: =VLOOKUP(B19,Registration!$B$3:$C$77,2,FALSE) -> 10 | F19: 16 | G19: 63 | H19: 0.11116898 | I19: =H19-'Leg 1'!C21 -> 0.065289352 | J19: =VLOOKUP(G19,[1]Registration!$B$3:$C$77,2,FALSE) -> 10 | K19: 3 | L19: =I19/13.1 -> 0.00498392
A20: 17 | B20: 17 | C20: 0.11189815 | D20: ='leg 2'!C20-'Leg 1'!C20 -> 0.0671875 | E20: =VLOOKUP(B20,Registration!$B$3:$C$77,2,FALSE) -> 6 | F20: 17 | G20: 17 | H20: 0.11189815 | I20: =H20-'Leg 1'!C23 -> 0.065509259 | J20: =VLOOKUP(G20,[1]Registration!$B$3:$C$77,2,FALSE) -> 6 | K20: 2 | L20: =I20/13.1 -> 0.0050007068
A21: 18 | B21: 58 | C21: 0.11357639 | D21: ='leg 2'!C21-'Leg 1'!C21 -> 0.067696759 | E21: =VLOOKUP(B21,Registration!$B$3:$C$77,2,FALSE) -> 10 | F21: 18 | G21: 58 | H21: 0.11357639 | I21: =H21-'Leg 1'!C25 -> 0.066851852 | J21: =VLOOKUP(G21,[1]Registration!$B$3:$C$77,2,FALSE) -> 10 | K21: 4 | L21: =I21/13.1 -> 0.0051031948
A22: 19 | B22: 44 | C22: 0.11444444 | D22: ='leg 2'!C22-'Leg 1'!C22 -> 0.068402778 | E22: =VLOOKUP(B22,Registration!$B$3:$C$77,2,FALSE) -> 8 | F22: 19 | G22: 44 | H22: 0.11444444 | I22: =H22-'Leg 1'!C34 -> 0.062650463 | J22: =VLOOKUP(G22,[1]Registration!$B$3:$C$77,2,FALSE) -> 8 | K22: 4 | L22: =I22/13.1 -> 0.0047824781
A23: 20 | B23: 22 | C23: 0.11488426 | D23: ='leg 2'!C23-'Leg 1'!C23 -> 0.06849537 | E23: =VLOOKUP(B23,Registration!$B$3:$C$77,2,FALSE) -> 7 | F23: 20 | G23: 22 | H23: 0.11488426 | I23: =H23-'Leg 1'!C18 -> 0.070729167 | J23: =VLOOKUP(G23,[1]Registration!$B$3:$C$77,2,FALSE) -> 7 | K23: 1 | L23: =I23/13.1 -> 0.005399173
A24: 21 | B24: 53 | C24: 0.11509259 | D24: ='leg 2'!C24-'Leg 1'!C24 -> 0.068564815 | E24: =VLOOKUP(B24,Registration!$B$3:$C$77,2,FALSE) -> 9 | F24: 21 | G24: 53 | H24: 0.11509259 | I24: =H24-'Leg 1'!C29 -> 0.066712963 | J24: =VLOOKUP(G24,[1]Registration!$B$3:$C$77,2,FALSE) -> 9 | K24: 2 | L24: =I24/13.1 -> 0.0050925926
A25: 22 | B25: 62 | C25: 0.11592593 | D25: ='leg 2'!C25-'Leg 1'!C25 -> 0.069201389 | E25: =VLOOKUP(B25,Registration!$B$3:$C$77,2,FALSE) -> 10 | F25: 22 | G25: 62 | H25: 0.11592593 | I25: =H25-'Leg 1'!C24 -> 0.069398148 | J25: =VLOOKUP(G25,[1]Registration!$B$3:$C$77,2,FALSE) -> 10 | K25: 4 | L25: =I25/13.1 -> 0.0052975686
A26: 23 | B26: 34 | C26: 0.11775463 | D26: ='leg 2'!C26-'Leg 1'!C26 -> 0.070138889 | E26: =VLOOKUP(B26,Registration!$B$3:$C$77,2,FALSE) -> 8 | F26: 23 | G26: 34 | H26: 0.11775463 | I26: =H26-'Leg 1'!C26 -> 0.070138889 | J26: =VLOOKUP(G26,[1]Registration!$B$3:$C$77,2,FALSE) -> 8 | K26: 5 | L26: =I26/13.1 -> 0.0053541137
A27: 24 | B27: 15 | C27: 0.11988426 | D27: ='leg 2'!C27-'Leg 1'!C27 -> 0.071898148 | E27: =VLOOKUP(B27,Registration!$B$3:$C$77,2,FALSE) -> 6 | F27: 24 | G27: 15 | H27: 0.11988426 | I27: =H27-'Leg 1'!C45 -> 0.064710648 | J27: =VLOOKUP(G27,[1]Registration!$B$3:$C$77,2,FALSE) -> 6 | K27: 3 | L27: =I27/13.1 -> 0.0049397441
A28: 25 | B28: 30 | C28: 0.12069444 | D28: ='leg 2'!C28-'Leg 1'!C28 -> 0.072453704 | E28: =VLOOKUP(B28,Registration!$B$3:$C$77,2,FALSE) -> 8 | F28: 25 | G28: 30 | H28: 0.12069444 | I28: =H28-'Leg 1'!C41 -> 0.067291667 | J28: =VLOOKUP(G28,[1]Registration!$B$3:$C$77,2,FALSE) -> 8 | K28: 6 | L28: =I28/13.1 -> 0.0051367684
A29: 26 | B29: 46 | C29: 0.12155093 | D29: ='leg 2'!C29-'Leg 1'!C29 -> 0.073171296 | E29: =VLOOKUP(B29,Registration!$B$3:$C$77,2,FALSE) -> 8 | F29: 26 | G29: 46 | H29: 0.12155093 | I29: =H29-'Leg 1'!C22 -> 0.075509259 | J29: =VLOOKUP(G29,[1]Registration!$B$3:$C$77,2,FALSE) -> 8 | K29: 7 | L29: =I29/13.1 -> 0.0057640656
A30: 27 | B30: 56 | C30: 0.12405093 | D30: ='leg 2'!C30-'Leg 1'!C30 -> 0.075347222 | E30: =VLOOKUP(B30,Registration!$B$3:$C$77,2,FALSE) -> 9 | F30: 27 | G30: 56 | H30: 0.12405093 | I30: =H30-'Leg 1'!C33 -> 0.072766204 | J30: =VLOOKUP(G30,[1]Registration!$B$3:$C$77,2,FALSE) -> 9 | K30: 3 | L30: =I30/13.1 -> 0.005554672
A31: 28 | B31: 29 | C31: 0.12459491 | D31: ='leg 2'!C31-'Leg 1'!C31 -> 0.074780093 | E31: =VLOOKUP(B31,Registration!$B$3:$C$77,2,FALSE) -> 8 | F31: 28 | G31: 29 | H31: 0.12459491 | I31: =H31-'Leg 1'!C48 -> 0.068009259 | J31: =VLOOKUP(G31,[1]Registration!$B$3:$C$77,2,FALSE) -> 8 | K31: 8 | L31: =I31/13.1 -> 0.0051915465
A32: 29 | B32: 31 | C32: 0.12525463 | D32: ='leg 2'!C32-'Leg 1'!C32 -> 0.074085648 | E32: =VLOOKUP(B32,Registration!$B$3:$C$77,2,FALSE) -> 8 | F32: 29 | G32: 31 | H32: 0.12525463 | I32: =H32-'Leg 1'!C37 -> 0.072650463 | J32: =VLOOKUP(G32,[1]Registration!$B$3:$C$77,2,FALSE) -> 8 | K32: 9 | L32: =I32/13.1 -> 0.0055458369
A33: 30 | B33: 25 | C33: 0.12584491 | D33: ='leg 2'!C33-'Leg 1'!C33 -> 0.074560185 | E33: =VLOOKUP(B33,Registration!$B$3:$C$77,2,FALSE) -> 7 | F33: 30 | G33: 25 | H33: 0.12584491 | I33: =H33-'Leg 1'!C30 -> 0.077141204 | J33: =VLOOKUP(G33,[1]Registration!$B$3:$C$77,2,FALSE) -> 7 | K33: 2 | L33: =I33/13.1 -> 0.0058886415
A34: 31 | B34: 57 | C34: 0.12601852 | D34: ='leg 2'!C34-'Leg 1'!C34 -> 0.074224537 | E34: =VLOOKUP(B34,Registration!$B$3:$C$77,2,FALSE) -> 9 | F34: 31 | G34: 57 | H34: 0.12601852 | I34: =H34-'Leg 1'!C33 -> 0.074733796 | J34: =VLOOKUP(G34,[1]Registration!$B$3:$C$77,2,FALSE) -> 9 | K34: 4 | L34: =I34/13.1 -> 0.0057048699
A35: 32 | B35: 20 | C35: 0.12658565 | D35: ='leg 2'!C35-'Leg 1'!C35 -> 0.074710648 | E35: =VLOOKUP(B35,Registration!$B$3:$C$77,2,FALSE) -> 6 | F35: 32 | G35: 20 | H35: 0.12658565 | I35: =H35-'Leg 1'!C31 -> 0.076770833 | J35: =VLOOKUP(G35,[1]Registration!$B$3:$C$77,2,FALSE) -> 6 | K35: 4 | L35: =I35/13.1 -> 0.005860369
A36: 33 | B36: 32 | C36: 0.1268287 | D36: ='leg 2'!C36-'Leg 1'!C36 -> 0.074386574 | E36: =VLOOKUP(B36,Registration!$B$3:$C$77,2,FALSE) -> 8 | F36: 33 | G36: 32 | H36: 0.1268287 | I36: =H36-'Leg 1'!C20 -> 0.082118056 | J36: =VLOOKUP(G36,[1]Registration!$B$3:$C$77,2,FALSE) -> 8 | K36: 10 | L36: =I36/13.1 -> 0.0062685539
A37: 34 | B37: 16 | C37: 0.12887731 | D37: ='leg 2'!C37-'Leg 1'!C37 -> 0.076273148 | E37: =VLOOKUP(B37,Registration!$B$3:$C$77,2,FALSE) -> 6 | F37: 34 | G37: 16 | H37: 0.12887731 | I37: =H37-'Leg 1'!C39 -> 0.075972222 | J37: =VLOOKUP(G37,[1]Registration!$B$3:$C$77,2,FALSE) -> 6 | K37: 4 | L37: =I37/13.1 -> 0.0057994063
A38: 35 | B38: 61 | C38: 0.13016204 | D38: ='leg 2'!C38-'Leg 1'!C38 -> 0.077546296 | E38: =VLOOKUP(B38,Registration!$B$3:$C$77,2,FALSE) -> 10 | F38: 35 | G38: 61 | H38: 0.13016204 | I38: =H38-'Leg 1'!C35 -> 0.078287037 | J38: =VLOOKUP(G38,[1]Registration!$B$3:$C$77,2,FALSE) -> 10 | K38: 5 | L38: =I38/13.1 -> 0.0059761097
A39: 36 | B39: 33 | C39: 0.13027778 | D39: ='leg 2'!C39-'Leg 1'!C39 -> 0.077372685 | E39: =VLOOKUP(B39,Registration!$B$3:$C$77,2,FALSE) -> 8 | F39: 36 | G39: 33 | H39: 0.13027778 | I39: =H39-'Leg 1'!C57 -> 0.068842593 | J39: =VLOOKUP(G39,[1]Registration!$B$3:$C$77,2,FALSE) -> 8 | K39: 11 | L39: =I39/13.1 -> 0.0052551597
A40: 37 | B40: 11 | C40: 0.13347222 | D40: ='leg 2'!C40-'Leg 1'!C40 -> 0.080185185 | E40: =VLOOKUP(B40,Registration!$B$3:$C$77,2,FALSE) -> 3 | F40: 37 | G40: 11 | H40: 0.13347222 | I40: =H40-'Leg 1'!C36 -> 0.081030093 | J40: =VLOOKUP(G40,[1]Registration!$B$3:$C$77,2,FALSE) -> 3 | K40: 1 | L40: =I40/13.1 -> 0.0061855033
...

Sheet Leg 3
A1: Leg 3 | B1: 2017 Tahoe Relay
G2: 9.6 miles
A3: Place | B3: Bib # | C3: Total Time | D3: Leg Time | E3: Div | F3: Div Place | G3: Pace
A4: 1 | B4: 68 | C4: 0.12679398 | D4: =C4-'leg 2'!H4 -> 0.03849537 | E4: =VLOOKUP(B4,Registration!$B$3:$C$77,2,FALSE) -> 1 | F4: 1 | G4: =D4/9.6 -> 0.0040099344
A5: 2 | B5: 1 | C5: 0.12943287 | D5: =C5-'leg 2'!H5 -> 0.038310185 | E5: =VLOOKUP(B5,Registration!$B$3:$C$77,2,FALSE) -> 1 | F5: 2 | G5: =D5/9.6 -> 0.0039906443
A6: 3 | B6: 5 | C6: 0.13413194 | D6: =C6-'leg 2'!H7 -> 0.039907407 | E6: =VLOOKUP(B6,Registration!$B$3:$C$77,2,FALSE) -> 1 | F6: 3 | G6: =D6/9.6 -> 0.0041570216
A7: 4 | B7: 7 | C7: 0.13548611 | D7: =C7-'leg 2'!H6 -> 0.041689815 | E7: =VLOOKUP(B7,Registration!$B$3:$C$77,2,FALSE) -> 1 | F7: 4 | G7: =D7/9.6 -> 0.004342689
A8: 5 | B8: 2 | C8: 0.13756944 | D8: =C8-'leg 2'!H8 -> 0.041793981 | E8: =VLOOKUP(B8,Registration!$B$3:$C$77,2,FALSE) -> 1 | F8: 5 | G8: =D8/9.6 -> 0.0043535397
A9: 6 | B9: 9 | C9: 0.13916667 | D9: =C9-'leg 2'!H9 -> 0.043148148 | E9: =VLOOKUP(B9,Registration!$B$3:$C$77,2,FALSE) -> 2 | F9: 1 | G9: =D9/9.6 -> 0.0044945988
A10: 7 | B10: 18 | C10: 0.14416667 | D10: =C10-'leg 2'!H11 -> 0.045717593 | E10: =VLOOKUP(B10,Registration!$B$3:$C$77,2,FALSE) -> 6 | F10: 1 | G10: =D10/9.6 -> 0.0047622492
A11: 8 | B11: 47 | C11: 0.14466435 | D11: =C11-'leg 2'!H10 -> 0.047453704 | E11: =VLOOKUP(B11,Registration!$B$3:$C$77,2,FALSE) -> 8 | F11: 1 | G11: =D11/9.6 -> 0.0049430941
A12: 9 | B12: 43 | C12: 0.15056713 | D12: =C12-'leg 2'!H14 -> 0.047060185 | E12: =VLOOKUP(B12,Registration!$B$3:$C$77,2,FALSE) -> 8 | F12: 2 | G12: =D12/9.6 -> 0.0049021026
A13: 10 | B13: 6 | C13: 0.15481481 | D13: =C13-'leg 2'!H12 -> 0.053634259 | E13: =VLOOKUP(B13,Registration!$B$3:$C$77,2,FALSE) -> 1 | F13: 6 | G13: =D13/9.6 -> 0.005586902
A14: 11 | B14: 63 | C14: 0.15778935 | D14: =C14-'leg 2'!H19 -> 0.04662037 | E14: =VLOOKUP(B14,Registration!$B$3:$C$77,2,FALSE) -> 10 | F14: 1 | G14: =D14/9.6 -> 0.0048562886
A15: 12 | B15: 59 | C15: 0.15790509 | D15: =C15-'leg 2'!H16 -> 0.051041667 | E15: =VLOOKUP(B15,Registration!$B$3:$C$77,2,FALSE) -> 10 | F15: 2 | G15: =D15/9.6 -> 0.0053168403
A16: 13 | B16: 45 | C16: 0.15940972 | D16: =C16-'leg 2'!H15 -> 0.053217593 | E16: =VLOOKUP(B16,Registration!$B$3:$C$77,2,FALSE) -> 8 | F16: 3 | G16: =D16/9.6 -> 0.0055434992
A17: 14 | B17: 17 | C17: 0.16005787 | D17: =C17-'leg 2'!H20 -> 0.048159722 | E17: =VLOOKUP(B17,Registration!$B$3:$C$77,2,FALSE) -> 6 | F17: 2 | G17: =D17/9.6 -> 0.0050166377
A18: 15 | B18: 65 | C18: 0.16023148 | D18: =C18-'leg 2'!H18 -> 0.04912037 | E18: =VLOOKUP(B18,Registration!$B$3:$C$77,2,FALSE) -> 10 | F18: 3 | G18: =D18/9.6 -> 0.0051167052
A19: 16 | B19: 4 | C19: 0.16292824 | D19: =C19-'leg 2'!H17 -> 0.053969907 | E19: =VLOOKUP(B19,Registration!$B$3:$C$77,2,FALSE) -> 1 | F19: 7 | G19: =D19/9.6 -> 0.0056218654
A20: 17 | B20: 58 | C20: 0.16502315 | D20: =C20-'leg 2'!H21 -> 0.051446759 | E20: =VLOOKUP(B20,Registration!$B$3:$C$77,2,FALSE) -> 10 | F20: 4 | G20: =D20/9.6 -> 0.0053590374
A21: 18 | B21: 62 | C21: 0.16528935 | D21: =C21-'leg 2'!H25 -> 0.049363426 | E21: =VLOOKUP(B21,Registration!$B$3:$C$77,2,FALSE) -> 10 | F21: 5 | G21: =D21/9.6 -> 0.0051420235
A22: 19 | B22: 34 | C22: 0.16677083 | D22: =C22-'leg 2'!H26 -> 0.049016204 | E22: =VLOOKUP(B22,Registration!$B$3:$C$77,2,FALSE) -> 8 | F22: 4 | G22: =D22/9.6 -> 0.0051058546
A23: 20 | B23: 53 | C23: 0.16711806 | D23: =C23-'leg 2'!H24 -> 0.052025463 | E23: =VLOOKUP(B23,Registration!$B$3:$C$77,2,FALSE) -> 9 | F23: 1 | G23: =D23/9.6 -> 0.0054193191
A24: 21 | B24: 15 | C24: 0.17052083 | D24: =C24-'leg 2'!H27 -> 0.050636574 | E24: =VLOOKUP(B24,Registration!$B$3:$C$77,2,FALSE) -> 6 | F24: 3 | G24: =D24/9.6 -> 0.0052746431
A25: 22 | B25: 44 | C25: 0.17105324 | D25: =C25-'leg 2'!H22 -> 0.056608796 | E25: =VLOOKUP(B25,Registration!$B$3:$C$77,2,FALSE) -> 8 | F25: 4 | G25: =D25/9.6 -> 0.0058967496
A26: 23 | B26: 46 | C26: 0.17315972 | D26: =C26-'leg 2'!H29 -> 0.051608796 | E26: =VLOOKUP(B26,Registration!$B$3:$C$77,2,FALSE) -> 8 | F26: 5 | G26: =D26/9.6 -> 0.0053759163
A27: 24 | B27: 30 | C27: 0.17710648 | D27: =C27-'leg 2'!H28 -> 0.056412037 | E27: =VLOOKUP(B27,Registration!$B$3:$C$77,2,FALSE) -> 8 | F27: 6 | G27: =D27/9.6 -> 0.0058762539
A28: 25 | B28: 55 | C28: 0.17855324 | D28: =C28-'leg 2'!H13 -> 0.07599537 | E28: =VLOOKUP(B28,Registration!$B$3:$C$77,2,FALSE) -> 9 | F28: 2 | G28: =D28/9.6 -> 0.0079161844
A29: 26 | B29: 56 | C29: 0.17899306 | D29: =C29-'leg 2'!H30 -> 0.05494213 | E29: =VLOOKUP(B29,Registration!$B$3:$C$77,2,FALSE) -> 9 | F29: 3 | G29: =D29/9.6 -> 0.0057231385
A30: 27 | B30: 25 | C30: 0.18009259 | D30: =C30-'leg 2'!H33 -> 0.054247685 | E30: =VLOOKUP(B30,Registration!$B$3:$C$77,2,FALSE) -> 7 | F30: 1 | G30: =D30/9.6 -> 0.0056508005
A31: 28 | B31: 32 | C31: 0.18020833 | D31: =C31-'leg 2'!H36 -> 0.05337963 | E31: =VLOOKUP(B31,Registration!$B$3:$C$77,2,FALSE) -> 8 | F31: 7 | G31: =D31/9.6 -> 0.0055603781
A32: 29 | B32: 22 | C32: 0.180625 | D32: =C32-'leg 2'!H23 -> 0.065740741 | E32: =VLOOKUP(B32,Registration!$B$3:$C$77,2,FALSE) -> 7 | F32: 2 | G32: =D32/9.6 -> 0.0068479938
A33: 30 | B33: 33 | C33: 0.18141204 | D33: =C33-'leg 2'!H39 -> 0.051134259 | E33: =VLOOKUP(B33,Registration!$B$3:$C$77,2,FALSE) -> 8 | F33: 8 | G33: =D33/9.6 -> 0.0053264853
A34: 31 | B34: 31 | C34: 0.18219907 | D34: =C34-'leg 2'!H32 -> 0.056944444 | E34: =VLOOKUP(B34,Registration!$B$3:$C$77,2,FALSE) -> 8 | F34: 9 | G34: =D34/9.6 -> 0.005931713
A35: 32 | B35: 57 | C35: 0.18236111 | D35: =C35-'leg 2'!H34 -> 0.056342593 | E35: =VLOOKUP(B35,Registration!$B$3:$C$77,2,FALSE) -> 9 | F35: 4 | G35: =D35/9.6 -> 0.0058690201
A36: 33 | B36: 10 | C36: 0.1840625 | D36: =C36-'leg 2'!H48 -> 0.0434375 | E36: =VLOOKUP(B36,Registration!$B$3:$C$77,2,FALSE) -> 3 | F36: 1 | G36: =D36/9.6 -> 0.0045247396
A37: 34 | B37: 16 | C37: 0.1855787 | D37: =C37-'leg 2'!H37 -> 0.056701389 | E37: =VLOOKUP(B37,Registration!$B$3:$C$77,2,FALSE) -> 6 | F37: 4 | G37: =D37/9.6 -> 0.0059063947
A38: 35 | B38: 11 | C38: 0.18677083 | D38: =C38-'leg 2'!H40 -> 0.053298611 | E38: =VLOOKUP(B38,Registration!$B$3:$C$77,2,FALSE) -> 3 | F38: 2 | G38: =D38/9.6 -> 0.0055519387
A39: 36 | B39: 29 | C39: 0.18731481 | D39: =C39-'leg 2'!H31 -> 0.062719907 | E39: =VLOOKUP(B39,Registration!$B$3:$C$77,2,FALSE) -> 8 | F39: 10 | G39: =D39/9.6 -> 0.0065333237
A40: 37 | B40: 19 | C40: 0.18810185 | D40: =C40-'leg 2'!H43 -> 0.053310185 | E40: =VLOOKUP(B40,Registration!$B$3:$C$77,2,FALSE) -> 6 | F40: 5 | G40: =D40/9.6 -> 0.0055531443
...

Sheet Leg 4
A1: Leg 4 | B1: 2017 Tahoe Relay
G2: 9.5 miles
A3: Place | B3: Bib # | C3: Total Time | D3: Leg Time | E3: Div | F3: Div Place | G3: Pace
A4: 1 | B4: 68 | C4: 0.16359954 | D4: =C4-'Leg 3'!C4 -> 0.036805556 | E4: =VLOOKUP(B4,Registration!$B$3:$C$77,2,FALSE) -> 1 | F4: 1 | G4: =D4/9.5 -> 0.003874269
A5: 2 | B5: 1 | C5: 0.16717593 | D5: =C5-'Leg 3'!C5 -> 0.037743056 | E5: =VLOOKUP(B5,Registration!$B$3:$C$77,2,FALSE) -> 1 | F5: 2 | G5: =D5/9.5 -> 0.0039729532
A6: 3 | B6: 9 | C6: 0.17549769 | D6: =C6-'Leg 3'!C9 -> 0.036331019 | E6: =VLOOKUP(B6,Registration!$B$3:$C$77,2,FALSE) -> 2 | F6: 1 | G6: =D6/9.5 -> 0.0038243177
A7: 4 | B7: 7 | C7: 0.17715278 | D7: =C7-'Leg 3'!C7 -> 0.041666667 | E7: =VLOOKUP(B7,Registration!$B$3:$C$77,2,FALSE) -> 1 | F7: 3 | G7: =D7/9.5 -> 0.0043859649
A8: 5 | B8: 5 | C8: 0.17966435 | D8: =C8-'Leg 3'!C6 -> 0.045532407 | E8: =VLOOKUP(B8,Registration!$B$3:$C$77,2,FALSE) -> 1 | F8: 4 | G8: =D8/9.5 -> 0.004792885
A9: 6 | B9: 2 | C9: 0.18268519 | D9: =C9-'Leg 3'!C8 -> 0.045115741 | E9: =VLOOKUP(B9,Registration!$B$3:$C$77,2,FALSE) -> 1 | F9: 5 | G9: =D9/9.5 -> 0.0047490253
A10: 7 | B10: 18 | C10: 0.19079861 | D10: =C10-'Leg 3'!C10 -> 0.046631944 | E10: =VLOOKUP(B10,Registration!$B$3:$C$77,2,FALSE) -> 6 | F10: 1 | G10: =D10/9.5 -> 0.0049086257
A11: 8 | B11: 47 | C11: 0.19412037 | D11: =C11-'Leg 3'!C11 -> 0.049456019 | E11: =VLOOKUP(B11,Registration!$B$3:$C$77,2,FALSE) -> 8 | F11: 1 | G11: =D11/9.5 -> 0.0052058967
A12: 9 | B12: 43 | C12: 0.19982639 | D12: =C12-'Leg 3'!C12 -> 0.049259259 | E12: =VLOOKUP(B12,Registration!$B$3:$C$77,2,FALSE) -> 8 | F12: 2 | G12: =D12/9.5 -> 0.0051851852
A13: 10 | B13: 45 | C13: 0.2006713 | D13: =C13-'Leg 3'!C16 -> 0.041261574 | E13: =VLOOKUP(B13,Registration!$B$3:$C$77,2,FALSE) -> 8 | F13: 3 | G13: =D13/9.5 -> 0.0043433236
A14: 11 | B14: 59 | C14: 0.20386574 | D14: =C14-'Leg 3'!C15 -> 0.045960648 | E14: =VLOOKUP(B14,Registration!$B$3:$C$77,2,FALSE) -> 10 | F14: 1 | G14: =D14/9.5 -> 0.004837963
A15: 12 | B15: 6 | C15: 0.20702546 | D15: =C15-'Leg 3'!C13 -> 0.052210648 | E15: =VLOOKUP(B15,Registration!$B$3:$C$77,2,FALSE) -> 1 | F15: 6 | G15: =D15/9.5 -> 0.0054958577
A16: 13 | B16: 17 | C16: 0.20725694 | D16: =C16-'Leg 3'!C17 -> 0.047199074 | E16: =VLOOKUP(B16,Registration!$B$3:$C$77,2,FALSE) -> 6 | F16: 2 | G16: =D16/9.5 -> 0.0049683236
A17: 14 | B17: 63 | C17: 0.20803241 | D17: =C17-'Leg 3'!C14 -> 0.050243056 | E17: =VLOOKUP(B17,Registration!$B$3:$C$77,2,FALSE) -> 10 | F17: 2 | G17: =D17/9.5 -> 0.0052887427
A18: 15 | B18: 4 | C18: 0.21232639 | D18: =C18-'Leg 3'!C19 -> 0.049398148 | E18: =VLOOKUP(B18,Registration!$B$3:$C$77,2,FALSE) -> 1 | F18: 7 | G18: =D18/9.5 -> 0.0051998051
A19: 16 | B19: 58 | C19: 0.21234954 | D19: =C19-'Leg 3'!C20 -> 0.047326389 | E19: =VLOOKUP(B19,Registration!$B$3:$C$77,2,FALSE) -> 10 | F19: 3 | G19: =D19/9.5 -> 0.0049817251
A20: 17 | B20: 34 | C20: 0.21326389 | D20: =C20-'Leg 3'!C22 -> 0.046493056 | E20: =VLOOKUP(B20,Registration!$B$3:$C$77,2,FALSE) -> 8 | F20: 4 | G20: =D20/9.5 -> 0.0048940058
A21: 18 | B21: 53 | C21: 0.21516204 | D21: =C21-'Leg 3'!C23 -> 0.048043981 | E21: =VLOOKUP(B21,Registration!$B$3:$C$77,2,FALSE) -> 9 | F21: 1 | G21: =D21/9.5 -> 0.0050572612
A22: 19 | B22: 62 | C22: 0.21885417 | D22: =C22-'Leg 3'!C21 -> 0.053564815 | E22: =VLOOKUP(B22,Registration!$B$3:$C$77,2,FALSE) -> 10 | F22: 4 | G22: =D22/9.5 -> 0.0056384016
A23: 20 | B23: 65 | C23: 0.21981481 | D23: =C23-'Leg 3'!C18 -> 0.059583333 | E23: =VLOOKUP(B23,Registration!$B$3:$C$77,2,FALSE) -> 10 | F23: 5 | G23: =D23/9.5 -> 0.0062719298
A24: 21 | B24: 15 | C24: 0.22016204 | D24: =C24-'Leg 3'!C24 -> 0.049641204 | E24: =VLOOKUP(B24,Registration!$B$3:$C$77,2,FALSE) -> 6 | F24: 3 | G24: =D24/9.5 -> 0.0052253899
A25: 22 | B25: 46 | C25: 0.22814815 | D25: =C25-'Leg 3'!C26 -> 0.054988426 | E25: =VLOOKUP(B25,Registration!$B$3:$C$77,2,FALSE) -> 8 | F25: 5 | G25: =D25/9.5 -> 0.0057882554
A26: 23 | B26: 56 | C26: 0.22868056 | D26: =C26-'Leg 3'!C29 -> 0.0496875 | E26: =VLOOKUP(B26,Registration!$B$3:$C$77,2,FALSE) -> 9 | F26: 2 | G26: =D26/9.5 -> 0.0052302632
A27: 24 | B27: 44 | C27: 0.2315625 | D27: =C27-'Leg 3'!C25 -> 0.060509259 | E27: =VLOOKUP(B27,Registration!$B$3:$C$77,2,FALSE) -> 8 | F27: 6 | G27: =D27/9.5 -> 0.0063693957
A28: 25 | B28: 30 | C28: 0.23525463 | D28: =C28-'Leg 3'!C27 -> 0.058148148 | E28: =VLOOKUP(B28,Registration!$B$3:$C$77,2,FALSE) -> 8 | F28: 7 | G28: =D28/9.5 -> 0.0061208577
A29: 26 | B29: 61 | C29: 0.23547454 | D29: =C29-'Leg 3'!C41 -> 0.047152778 | E29: =VLOOKUP(B29,Registration!$B$3:$C$77,2,FALSE) -> 10 | F29: 6 | G29: =D29/9.5 -> 0.0049634503
A30: 27 | B30: 19 | C30: 0.23675926 | D30: =C30-'Leg 3'!C40 -> 0.048657407 | E30: =VLOOKUP(B30,Registration!$B$3:$C$77,2,FALSE) -> 6 | F30: 4 | G30: =D30/9.5 -> 0.0051218324
A31: 28 | B31: 57 | C31: 0.23821759 | D31: =C31-'Leg 3'!C35 -> 0.055856481 | E31: =VLOOKUP(B31,Registration!$B$3:$C$77,2,FALSE) -> 9 | F31: 3 | G31: =D31/9.5 -> 0.0058796296
A32: 29 | B32: 31 | C32: 0.23989583 | D32: =C32-'Leg 3'!C34 -> 0.057696759 | E32: =VLOOKUP(B32,Registration!$B$3:$C$77,2,FALSE) -> 8 | F32: 8 | G32: =D32/9.5 -> 0.0060733431
A33: 30 | B33: 22 | C33: 0.24032407 | D33: =C33-'Leg 3'!C32 -> 0.059699074 | E33: =VLOOKUP(B33,Registration!$B$3:$C$77,2,FALSE) -> 7 | F33: 1 | G33: =D33/9.5 -> 0.0062841131
A34: 31 | B34: 29 | C34: 0.24052083 | D34: =C34-'Leg 3'!C39 -> 0.053206019 | E34: =VLOOKUP(B34,Registration!$B$3:$C$77,2,FALSE) -> 8 | F34: 8 | G34: =D34/9.5 -> 0.0056006335
A35: 32 | B35: 11 | C35: 0.24208333 | D35: =C35-'Leg 3'!C38 -> 0.0553125 | E35: =VLOOKUP(B35,Registration!$B$3:$C$77,2,FALSE) -> 3 | F35: 1 | G35: =D35/9.5 -> 0.0058223684
A36: 33 | B36: 20 | C36: 0.24255787 | D36: =C36-'Leg 3'!C42 -> 0.053391204 | E36: =VLOOKUP(B36,Registration!$B$3:$C$77,2,FALSE) -> 6 | F36: 5 | G36: =D36/9.5 -> 0.0056201267
A37: 34 | B37: 32 | C37: 0.24287037 | D37: =C37-'Leg 3'!C31 -> 0.062662037 | E37: =VLOOKUP(B37,Registration!$B$3:$C$77,2,FALSE) -> 8 | F37: 9 | G37: =D37/9.5 -> 0.0065960039
A38: 35 | B38: 10 | C38: 0.24292824 | D38: =C38-'Leg 3'!C36 -> 0.058865741 | E38: =VLOOKUP(B38,Registration!$B$3:$C$77,2,FALSE) -> 3 | F38: 2 | G38: =D38/9.5 -> 0.0061963938
A39: 36 | B39: 16 | C39: 0.245 | D39: =C39-'Leg 3'!C37 -> 0.059421296 | E39: =VLOOKUP(B39,Registration!$B$3:$C$77,2,FALSE) -> 6 | F39: 6 | G39: =D39/9.5 -> 0.0062548733
A40: 37 | B40: 41 | C40: 0.2450463 | D40: =C40-'Leg 3'!C45 -> 0.048599537 | E40: =VLOOKUP(B40,Registration!$B$3:$C$77,2,FALSE) -> 8 | F40: 9 | G40: =D40/9.5 -> 0.0051157407
...

Sheet Leg 5
A1: Leg 5 | B1: 2017 Tahoe Relay
G2: 10.7 Miles
A3: Place | B3: Bib # | C3: Total Time | D3: Leg Time | E3: Div | F3: Div Place | G3: Pace
A4: 1 | B4: 68 | C4: 0.19872685 | D4: =C4-'Leg 4'!C4 -> 0.035127315 | E4: =VLOOKUP(B4,Registration!$B$3:$C$77,2,FALSE) -> 1 | F4: 1 | G4: =D4/10.7 -> 0.0032829266
A5: 2 | B5: 1 | C5: 0.20804398 | D5: =C5-'Leg 4'!C5 -> 0.040868056 | E5: =VLOOKUP(B5,Registration!$B$3:$C$77,2,FALSE) -> 1 | F5: 2 | G5: =D5/10.7 -> 0.0038194444
A6: 3 | B6: 7 | C6: 0.22209491 | D6: =C6-'Leg 4'!C7 -> 0.04494213 | E6: =VLOOKUP(B6,Registration!$B$3:$C$77,2,FALSE) -> 1 | F6: 3 | G6: =D6/10.7 -> 0.004200199
A7: 4 | B7: 9 | C7: 0.2233912 | D7: =C7-'Leg 4'!C6 -> 0.047893519 | E7: =VLOOKUP(B7,Registration!$B$3:$C$77,2,FALSE) -> 2 | F7: 1 | G7: =D7/10.7 -> 0.0044760298
A8: 5 | B8: 5 | C8: 0.22622685 | D8: =C8-'Leg 4'!C8 -> 0.0465625 | E8: =VLOOKUP(B8,Registration!$B$3:$C$77,2,FALSE) -> 1 | F8: 4 | G8: =D8/10.7 -> 0.0043516355
A9: 6 | B9: 2 | C9: 0.23096065 | D9: =C9-'Leg 4'!C9 -> 0.048275463 | E9: =VLOOKUP(B9,Registration!$B$3:$C$77,2,FALSE) -> 1 | F9: 5 | G9: =D9/10.7 -> 0.0045117255
A10: 7 | B10: 47 | C10: 0.24315972 | D10: =C10-'Leg 4'!C11 -> 0.049039352 | E10: =VLOOKUP(B10,Registration!$B$3:$C$77,2,FALSE) -> 8 | F10: 1 | G10: =D10/10.7 -> 0.004583117
A11: 8 | B11: 18 | C11: 0.24607639 | D11: =C11-'Leg 4'!C10 -> 0.055277778 | E11: =VLOOKUP(B11,Registration!$B$3:$C$77,2,FALSE) -> 6 | F11: 1 | G11: =D11/10.7 -> 0.0051661475
A12: 9 | B12: 43 | C12: 0.25123843 | D12: =C12-'Leg 4'!C12 -> 0.051412037 | E12: =VLOOKUP(B12,Registration!$B$3:$C$77,2,FALSE) -> 8 | F12: 2 | G12: =D12/10.7 -> 0.0048048633
A13: 10 | B13: 6 | C13: 0.25428241 | D13: =C13-'Leg 4'!C15 -> 0.047256944 | E13: =VLOOKUP(B13,Registration!$B$3:$C$77,2,FALSE) -> 1 | F13: 6 | G13: =D13/10.7 -> 0.0044165369
A14: 11 | B14: 59 | C14: 0.25967593 | D14: =C14-'Leg 4'!C14 -> 0.055810185 | E14: =VLOOKUP(B14,Registration!$B$3:$C$77,2,FALSE) -> 10 | F14: 1 | G14: =D14/10.7 -> 0.0052159052
A15: 12 | B15: 58 | C15: 0.26193287 | D15: =C15-'Leg 4'!C19 -> 0.049583333 | E15: =VLOOKUP(B15,Registration!$B$3:$C$77,2,FALSE) -> 10 | F15: 2 | G15: =D15/10.7 -> 0.0046339564
A16: 13 | B16: 17 | C16: 0.26199074 | D16: =C16-'Leg 4'!C16 -> 0.054733796 | E16: =VLOOKUP(B16,Registration!$B$3:$C$77,2,FALSE) -> 6 | F16: 2 | G16: =D16/10.7 -> 0.0051153081
A17: 14 | B17: 45 | C17: 0.2627662 | D17: =C17-'Leg 4'!C13 -> 0.062094907 | E17: =VLOOKUP(B17,Registration!$B$3:$C$77,2,FALSE) -> 8 | F17: 3 | G17: =D17/10.7 -> 0.0058032624
A18: 15 | B18: 63 | C18: 0.26409722 | D18: =C18-'Leg 4'!C17 -> 0.056064815 | E18: =VLOOKUP(B18,Registration!$B$3:$C$77,2,FALSE) -> 10 | F18: 3 | G18: =D18/10.7 -> 0.0052397023
A19: 16 | B19: 53 | C19: 0.26886574 | D19: =C19-'Leg 4'!C21 -> 0.053703704 | E19: =VLOOKUP(B19,Registration!$B$3:$C$77,2,FALSE) -> 9 | F19: 1 | G19: =D19/10.7 -> 0.0050190377
A20: 17 | B20: 34 | C20: 0.27008102 | D20: =C20-'Leg 4'!C20 -> 0.05681713 | E20: =VLOOKUP(B20,Registration!$B$3:$C$77,2,FALSE) -> 8 | F20: 3 | G20: =D20/10.7 -> 0.0053100121
A21: 18 | B21: 4 | C21: 0.27167824 | D21: =C21-'Leg 4'!C18 -> 0.059351852 | E21: =VLOOKUP(B21,Registration!$B$3:$C$77,2,FALSE) -> 1 | F21: 7 | G21: =D21/10.7 -> 0.005546902
A22: 19 | B22: 15 | C22: 0.27376157 | D22: =C22-'Leg 4'!C24 -> 0.053599537 | E22: =VLOOKUP(B22,Registration!$B$3:$C$77,2,FALSE) -> 6 | F22: 3 | G22: =D22/10.7 -> 0.0050093025
A23: 20 | B23: 62 | C23: 0.27601852 | D23: =C23-'Leg 4'!C22 -> 0.057164352 | E23: =VLOOKUP(B23,Registration!$B$3:$C$77,2,FALSE) -> 10 | F23: 4 | G23: =D23/10.7 -> 0.0053424628
A24: 21 | B24: 65 | C24: 0.27649306 | D24: =C24-'Leg 4'!C23 -> 0.056678241 | E24: =VLOOKUP(B24,Registration!$B$3:$C$77,2,FALSE) -> 10 | F24: 5 | G24: =D24/10.7 -> 0.0052970318
A25: 22 | B25: 44 | C25: 0.28109954 | D25: =C25-'Leg 4'!C27 -> 0.049537037 | E25: =VLOOKUP(B25,Registration!$B$3:$C$77,2,FALSE) -> 8 | F25: 4 | G25: =D25/10.7 -> 0.0046296296
A26: 23 | B26: 56 | C26: 0.28391204 | D26: =C26-'Leg 4'!C26 -> 0.055231481 | E26: =VLOOKUP(B26,Registration!$B$3:$C$77,2,FALSE) -> 9 | F26: 2 | G26: =D26/10.7 -> 0.0051618207
A27: 24 | B27: 46 | C27: 0.28784722 | D27: =C27-'Leg 4'!C25 -> 0.059699074 | E27: =VLOOKUP(B27,Registration!$B$3:$C$77,2,FALSE) -> 8 | F27: 5 | G27: =D27/10.7 -> 0.0055793527
A28: 25 | B28: 30 | C28: 0.29269676 | D28: =C28-'Leg 4'!C28 -> 0.05744213 | E28: =VLOOKUP(B28,Registration!$B$3:$C$77,2,FALSE) -> 8 | F28: 6 | G28: =D28/10.7 -> 0.0053684233
A29: 26 | B29: 41 | C29: 0.29476852 | D29: =C29-'Leg 4'!C40 -> 0.049722222 | E29: =VLOOKUP(B29,Registration!$B$3:$C$77,2,FALSE) -> 8 | F29: 7 | G29: =D29/10.7 -> 0.0046469367
A30: 27 | B30: 19 | C30: 0.29510417 | D30: =C30-'Leg 4'!C30 -> 0.058344907 | E30: =VLOOKUP(B30,Registration!$B$3:$C$77,2,FALSE) -> 6 | F30: 4 | G30: =D30/10.7 -> 0.0054527951
A31: 28 | B31: 29 | C31: 0.29528935 | D31: =C31-'Leg 4'!C34 -> 0.054768519 | E31: =VLOOKUP(B31,Registration!$B$3:$C$77,2,FALSE) -> 8 | F31: 8 | G31: =D31/10.7 -> 0.0051185531
A32: 29 | B32: 32 | C32: 0.29549769 | D32: =C32-'Leg 4'!C37 -> 0.052627315 | E32: =VLOOKUP(B32,Registration!$B$3:$C$77,2,FALSE) -> 8 | F32: 9 | G32: =D32/10.7 -> 0.0049184406
A33: 30 | B33: 57 | C33: 0.29550926 | D33: =C33-'Leg 4'!C31 -> 0.057291667 | E33: =VLOOKUP(B33,Registration!$B$3:$C$77,2,FALSE) -> 9 | F33: 3 | G33: =D33/10.7 -> 0.0053543614
A34: 31 | B34: 22 | C34: 0.29886574 | D34: =C34-'Leg 4'!C33 -> 0.058541667 | E34: =VLOOKUP(B34,Registration!$B$3:$C$77,2,FALSE) -> 7 | F34: 1 | G34: =D34/10.7 -> 0.0054711838
A35: 32 | B35: 31 | C35: 0.29980324 | D35: =C35-'Leg 4'!C32 -> 0.059907407 | E35: =VLOOKUP(B35,Registration!$B$3:$C$77,2,FALSE) -> 8 | F35: 10 | G35: =D35/10.7 -> 0.0055988231
A36: 33 | B36: 61 | C36: 0.30108796 | D36: =C36-'Leg 4'!C29 -> 0.065613426 | E36: =VLOOKUP(B36,Registration!$B$3:$C$77,2,FALSE) -> 10 | F36: 6 | G36: =D36/10.7 -> 0.0061320959
A37: 34 | B37: 16 | C37: 0.30358796 | D37: =C37-'Leg 4'!C39 -> 0.058587963 | E37: =VLOOKUP(B37,Registration!$B$3:$C$77,2,FALSE) -> 6 | F37: 5 | G37: =D37/10.7 -> 0.0054755106
A38: 35 | B38: 20 | C38: 0.30387731 | D38: =C38-'Leg 4'!C36 -> 0.061319444 | E38: =VLOOKUP(B38,Registration!$B$3:$C$77,2,FALSE) -> 6 | F38: 6 | G38: =D38/10.7 -> 0.0057307892
A39: 36 | B39: 11 | C39: 0.30395833 | D39: =C39-'Leg 4'!C35 -> 0.061875 | E39: =VLOOKUP(B39,Registration!$B$3:$C$77,2,FALSE) -> 3 | F39: 1 | G39: =D39/10.7 -> 0.0057827103
A40: 37 | B40: 25 | C40: 0.30989583 | D40: =C40-'Leg 4'!C41 -> 0.063506944 | E40: =VLOOKUP(B40,Registration!$B$3:$C$77,2,FALSE) -> 7 | F40: 2 | G40: =D40/10.7 -> 0.0059352285
...

Sheet Leg 6
A1: Leg 6 | B1: 2017 Tahoe Relay
G2: 8.6 Miles
A3: Place | B3: Bib # | C3: Total Time | D3: Leg Time | E3: Div | F3: Div Place | G3: Pace
A4: 1 | B4: 68 | C4: 0.24371528 | D4: =C4-'Leg 5'!C4 -> 0.044988426 | E4: =VLOOKUP(B4,Registration!$B$3:$C$77,2,FALSE) -> 1 | F4: 1 | G4: =D4/8.6 -> 0.0052312123
A5: 2 | B5: 1 | C5: 0.24396991 | D5: =C5-'Leg 5'!C5 -> 0.035925926 | E5: =VLOOKUP(B5,Registration!$B$3:$C$77,2,FALSE) -> 1 | F5: 2 | G5: =D5/8.6 -> 0.0041774332
A6: 3 | B6: 7 | C6: 0.25980324 | D6: =C6-'Leg 5'!C6 -> 0.037708333 | E6: =VLOOKUP(B6,Registration!$B$3:$C$77,2,FALSE) -> 1 | F6: 3 | G6: =D6/8.6 -> 0.0043846899
A7: 4 | B7: 9 | C7: 0.26459491 | D7: =C7-'Leg 5'!C7 -> 0.041203704 | E7: =VLOOKUP(B7,Registration!$B$3:$C$77,2,FALSE) -> 2 | F7: 1 | G7: =D7/8.6 -> 0.0047911283
A8: 5 | B8: 5 | C8: 0.26476852 | D8: =C8-'Leg 5'!C8 -> 0.038541667 | E8: =VLOOKUP(B8,Registration!$B$3:$C$77,2,FALSE) -> 1 | F8: 4 | G8: =D8/8.6 -> 0.0044815891
A9: 6 | B9: 2 | C9: 0.27131944 | D9: =C9-'Leg 5'!C9 -> 0.040358796 | E9: =VLOOKUP(B9,Registration!$B$3:$C$77,2,FALSE) -> 1 | F9: 5 | G9: =D9/8.6 -> 0.0046928833
A10: 7 | B10: 18 | C10: 0.28765046 | D10: =C10-'Leg 5'!C11 -> 0.041574074 | E10: =VLOOKUP(B10,Registration!$B$3:$C$77,2,FALSE) -> 6 | F10: 1 | G10: =D10/8.6 -> 0.0048341947
A11: 8 | B11: 47 | C11: 0.28840278 | D11: =C11-'Leg 5'!C10 -> 0.045243056 | E11: =VLOOKUP(B11,Registration!$B$3:$C$77,2,FALSE) -> 8 | F11: 1 | G11: =D11/8.6 -> 0.0052608204
A12: 9 | B12: 43 | C12: 0.29693287 | D12: =C12-'Leg 5'!C12 -> 0.045694444 | E12: =VLOOKUP(B12,Registration!$B$3:$C$77,2,FALSE) -> 8 | F12: 2 | G12: =D12/8.6 -> 0.0053133075
A13: 10 | B13: 59 | C13: 0.30179398 | D13: =C13-'Leg 5'!C14 -> 0.042118056 | E13: =VLOOKUP(B13,Registration!$B$3:$C$77,2,FALSE) -> 10 | F13: 1 | G13: =D13/8.6 -> 0.0048974483
A14: 11 | B14: 17 | C14: 0.30670139 | D14: =C14-'Leg 5'!C16 -> 0.044710648 | E14: =VLOOKUP(B14,Registration!$B$3:$C$77,2,FALSE) -> 6 | F14: 2 | G14: =D14/8.6 -> 0.0051989126
A15: 12 | B15: 58 | C15: 0.30677083 | D15: =C15-'Leg 5'!C15 -> 0.044837963 | E15: =VLOOKUP(B15,Registration!$B$3:$C$77,2,FALSE) -> 10 | F15: 2 | G15: =D15/8.6 -> 0.0052137166
A16: 13 | B16: 63 | C16: 0.30922454 | D16: =C16-'Leg 5'!C18 -> 0.045127315 | E16: =VLOOKUP(B16,Registration!$B$3:$C$77,2,FALSE) -> 10 | F16: 3 | G16: =D16/8.6 -> 0.0052473622
A17: 14 | B17: 6 | C17: 0.30950231 | D17: =C17-'Leg 5'!C13 -> 0.055219907 | E17: =VLOOKUP(B17,Registration!$B$3:$C$77,2,FALSE) -> 1 | F17: 6 | G17: =D17/8.6 -> 0.0064209195
A18: 15 | B18: 4 | C18: 0.31020833 | D18: =C18-'Leg 5'!C21 -> 0.038530093 | E18: =VLOOKUP(B18,Registration!$B$3:$C$77,2,FALSE) -> 1 | F18: 7 | G18: =D18/8.6 -> 0.0044802433
A19: 16 | B19: 45 | C19: 0.31101852 | D19: =C19-'Leg 5'!C17 -> 0.048252315 | E19: =VLOOKUP(B19,Registration!$B$3:$C$77,2,FALSE) -> 8 | F19: 3 | G19: =D19/8.6 -> 0.0056107343
A20: 17 | B20: 53 | C20: 0.31518519 | D20: =C20-'Leg 5'!C19 -> 0.046319444 | E20: =VLOOKUP(B20,Registration!$B$3:$C$77,2,FALSE) -> 9 | F20: 1 | G20: =D20/8.6 -> 0.0053859819
A21: 18 | B21: 34 | C21: 0.3178125 | D21: =C21-'Leg 5'!C20 -> 0.047731481 | E21: =VLOOKUP(B21,Registration!$B$3:$C$77,2,FALSE) -> 8 | F21: 4 | G21: =D21/8.6 -> 0.0055501723
A22: 19 | B22: 15 | C22: 0.31802083 | D22: =C22-'Leg 5'!C22 -> 0.044259259 | E22: =VLOOKUP(B22,Registration!$B$3:$C$77,2,FALSE) -> 6 | F22: 3 | G22: =D22/8.6 -> 0.0051464255
A23: 20 | B23: 62 | C23: 0.31829861 | D23: =C23-'Leg 5'!C23 -> 0.042280093 | E23: =VLOOKUP(B23,Registration!$B$3:$C$77,2,FALSE) -> 10 | F23: 4 | G23: =D23/8.6 -> 0.0049162898
A24: 21 | B24: 44 | C24: 0.33231481 | D24: =C24-'Leg 5'!C25 -> 0.051215278 | E24: =VLOOKUP(B24,Registration!$B$3:$C$77,2,FALSE) -> 8 | F24: 5 | G24: =D24/8.6 -> 0.0059552649
A25: 22 | B25: 65 | C25: 0.33572917 | D25: =C25-'Leg 5'!C24 -> 0.059236111 | E25: =VLOOKUP(B25,Registration!$B$3:$C$77,2,FALSE) -> 10 | F25: 5 | G25: =D25/8.6 -> 0.0068879199
A26: 23 | B26: 46 | C26: 0.33862269 | D26: =C26-'Leg 5'!C27 -> 0.050775463 | E26: =VLOOKUP(B26,Registration!$B$3:$C$77,2,FALSE) -> 8 | F26: 6 | G26: =D26/8.6 -> 0.0059041236
A27: 24 | B27: 30 | C27: 0.34097222 | D27: =C27-'Leg 5'!C28 -> 0.048275463 | E27: =VLOOKUP(B27,Registration!$B$3:$C$77,2,FALSE) -> 8 | F27: 7 | G27: =D27/8.6 -> 0.0056134259
A28: 25 | B28: 56 | C28: 0.34168981 | D28: =C28-'Leg 5'!C26 -> 0.057777778 | E28: =VLOOKUP(B28,Registration!$B$3:$C$77,2,FALSE) -> 9 | F28: 2 | G28: =D28/8.6 -> 0.0067183463
A29: 26 | B29: 22 | C29: 0.3437963 | D29: =C29-'Leg 5'!C34 -> 0.044930556 | E29: =VLOOKUP(B29,Registration!$B$3:$C$77,2,FALSE) -> 7 | F29: 1 | G29: =D29/8.6 -> 0.0052244832
A30: 27 | B30: 57 | C30: 0.34971065 | D30: =C30-'Leg 5'!C14 -> 0.090034722 | E30: =VLOOKUP(B30,Registration!$B$3:$C$77,2,FALSE) -> 9 | F30: 5 | G30: =D30/8.6 -> 0.010469154
A31: 28 | B31: 61 | C31: 0.35017361 | D31: =C31-'Leg 5'!C36 -> 0.049085648 | E31: =VLOOKUP(B31,Registration!$B$3:$C$77,2,FALSE) -> 10 | F31: 6 | G31: =D31/8.6 -> 0.0057076335
A32: 29 | B32: 41 | C32: 0.35101852 | D32: =C32-'Leg 5'!C29 -> 0.05625 | E32: =VLOOKUP(B32,Registration!$B$3:$C$77,2,FALSE) -> 8 | F32: 8 | G32: =D32/8.6 -> 0.0065406977
A33: 30 | B33: 29 | C33: 0.35230324 | D33: =C33-'Leg 5'!C31 -> 0.057013889 | E33: =VLOOKUP(B33,Registration!$B$3:$C$77,2,FALSE) -> 8 | F33: 2 | G33: =D33/8.6 -> 0.006629522
A34: 31 | B34: 20 | C34: 0.35277778 | D34: =C34-'Leg 5'!C38 -> 0.048900463 | E34: =VLOOKUP(B34,Registration!$B$3:$C$77,2,FALSE) -> 6 | F34: 4 | G34: =D34/8.6 -> 0.0056861003
A35: 32 | B35: 11 | C35: 0.35296296 | D35: =C35-'Leg 5'!C39 -> 0.04900463 | E35: =VLOOKUP(B35,Registration!$B$3:$C$77,2,FALSE) -> 3 | F35: 1 | G35: =D35/8.6 -> 0.0056982127
A36: 33 | B36: 19 | C36: 0.3544213 | D36: =C36-'Leg 5'!C30 -> 0.05931713 | E36: =VLOOKUP(B36,Registration!$B$3:$C$77,2,FALSE) -> 6 | F36: 5 | G36: =D36/8.6 -> 0.0068973407
A37: 34 | B37: 31 | C37: 0.35488426 | D37: =C37-'Leg 5'!C35 -> 0.055081019 | E37: =VLOOKUP(B37,Registration!$B$3:$C$77,2,FALSE) -> 8 | F37: 9 | G37: =D37/8.6 -> 0.0064047696
A38: 35 | B38: 32 | C38: 0.35572917 | D38: =C38-'Leg 5'!C32 -> 0.060231481 | E38: =VLOOKUP(B38,Registration!$B$3:$C$77,2,FALSE) -> 8 | F38: 10 | G38: =D38/8.6 -> 0.0070036606
A39: 36 | B39: 10 | C39: 0.36052083 | D39: =C39-'Leg 5'!C41 -> 0.047673611 | E39: =VLOOKUP(B39,Registration!$B$3:$C$77,2,FALSE) -> 3 | F39: 2 | G39: =D39/8.6 -> 0.0055434432
A40: 37 | B40: 33 | C40: 0.36837963 | D40: =C40-'Leg 5'!C36 -> 0.067291667 | E40: =VLOOKUP(B40,Registration!$B$3:$C$77,2,FALSE) -> 8 | F40: 11 | G40: =D40/8.6 -> 0.0078246124
...

Sheet Leg 7
A1: Leg 7 | B1: 2017 Tahoe Relay
G2: 11 Miles
A3: Place | B3: Bib # | C3: Total Time | D3: Leg Time | E3: Div | F3: Div Place | G3: Pace
A4: 1 | B4: 1 | C4: 0.28646991 | D4: =C4-'Leg 6'!C5 -> 0.0425 | E4: =VLOOKUP(B4,Registration!$B$3:$C$77,2,FALSE) -> 1 | F4: 1 | G4: =D4/11.1 -> 0.0038288288
A5: 2 | B5: 68 | C5: 0.28778935 | D5: =C5-'Leg 6'!C4 -> 0.044074074 | E5: =VLOOKUP(B5,Registration!$B$3:$C$77,2,FALSE) -> 1 | F5: 2 | G5: =D5/11.1 -> 0.0039706373
A6: 3 | B6: 7 | C6: 0.30519676 | D6: =C6-'Leg 6'!C6 -> 0.045393519 | E6: =VLOOKUP(B6,Registration!$B$3:$C$77,2,FALSE) -> 1 | F6: 3 | G6: =D6/11.1 -> 0.0040895062
A7: 4 | B7: 5 | C7: 0.31356481 | D7: =C7-'Leg 6'!C8 -> 0.048796296 | E7: =VLOOKUP(B7,Registration!$B$3:$C$77,2,FALSE) -> 1 | F7: 4 | G7: =D7/11.1 -> 0.0043960627
A8: 5 | B8: 9 | C8: 0.31668981 | D8: =C8-'Leg 6'!C7 -> 0.052094907 | E8: =VLOOKUP(B8,Registration!$B$3:$C$77,2,FALSE) -> 2 | F8: 1 | G8: =D8/11.1 -> 0.0046932349
A9: 6 | B9: 2 | C9: 0.31797454 | D9: =C9-'Leg 6'!C9 -> 0.046655093 | E9: =VLOOKUP(B9,Registration!$B$3:$C$77,2,FALSE) -> 1 | F9: 5 | G9: =D9/11.1 -> 0.0042031615
A10: 7 | B10: 18 | C10: 0.33782407 | D10: =C10-'Leg 6'!C10 -> 0.050173611 | E10: =VLOOKUP(B10,Registration!$B$3:$C$77,2,FALSE) -> 6 | F10: 1 | G10: =D10/11.1 -> 0.0045201451
A11: 8 | B11: 47 | C11: 0.33837963 | D11: =C11-'Leg 6'!C11 -> 0.049976852 | E11: =VLOOKUP(B11,Registration!$B$3:$C$77,2,FALSE) -> 8 | F11: 1 | G11: =D11/11.1 -> 0.0045024191
A12: 9 | B12: 43 | C12: 0.35443287 | D12: =C12-'Leg 6'!C12 -> 0.0575 | E12: =VLOOKUP(B12,Registration!$B$3:$C$77,2,FALSE) -> 8 | F12: 2 | G12: =D12/11.1 -> 0.0051801802
A13: 10 | B13: 59 | C13: 0.35488426 | D13: =C13-'Leg 6'!C13 -> 0.053090278 | E13: =VLOOKUP(B13,Registration!$B$3:$C$77,2,FALSE) -> 10 | F13: 1 | G13: =D13/11.1 -> 0.0047829079
A14: 11 | B14: 17 | C14: 0.35825231 | D14: =C14-'Leg 6'!C14 -> 0.051550926 | E14: =VLOOKUP(B14,Registration!$B$3:$C$77,2,FALSE) -> 6 | F14: 2 | G14: =D14/11.1 -> 0.0046442276
A15: 12 | B15: 58 | C15: 0.35827546 | D15: =C15-'Leg 6'!C15 -> 0.05150463 | E15: =VLOOKUP(B15,Registration!$B$3:$C$77,2,FALSE) -> 10 | F15: 3 | G15: =D15/11.1 -> 0.0046400567
A16: 13 | B16: 63 | C16: 0.36045139 | D16: =C16-'Leg 6'!C16 -> 0.051226852 | E16: =VLOOKUP(B16,Registration!$B$3:$C$77,2,FALSE) -> 10 | F16: 4 | G16: =D16/11.1 -> 0.0046150317
A17: 14 | B17: 45 | C17: 0.36180556 | D17: =C17-'Leg 6'!C19 -> 0.050787037 | E17: =VLOOKUP(B17,Registration!$B$3:$C$77,2,FALSE) -> 8 | F17: 3 | G17: =D17/11.1 -> 0.0045754087
A18: 15 | B18: 4 | C18: 0.36331019 | D18: =C18-'Leg 6'!C18 -> 0.053101852 | E18: =VLOOKUP(B18,Registration!$B$3:$C$77,2,FALSE) -> 1 | F18: 6 | G18: =D18/11.1 -> 0.0047839506
A19: 16 | B19: 6 | C19: 0.36965278 | D19: =C19-'Leg 6'!C17 -> 0.060150463 | E19: =VLOOKUP(B19,Registration!$B$3:$C$77,2,FALSE) -> 1 | F19: 7 | G19: =D19/11.1 -> 0.0054189606
A20: 17 | B20: 62 | C20: 0.37041667 | D20: =C20-'Leg 6'!C23 -> 0.052118056 | E20: =VLOOKUP(B20,Registration!$B$3:$C$77,2,FALSE) -> 10 | F20: 5 | G20: =D20/11.1 -> 0.0046953203
A21: 18 | B21: 15 | C21: 0.37049769 | D21: =C21-'Leg 6'!C22 -> 0.052476852 | E21: =VLOOKUP(B21,Registration!$B$3:$C$77,2,FALSE) -> 6 | F21: 3 | G21: =D21/11.1 -> 0.0047276443
A22: 19 | B22: 53 | C22: 0.37594907 | D22: =C22-'Leg 6'!C20 -> 0.060763889 | E22: =VLOOKUP(B22,Registration!$B$3:$C$77,2,FALSE) -> 9 | F22: 1 | G22: =D22/11.1 -> 0.0054742242
A23: 20 | B23: 34 | C23: 0.38576389 | D23: =C23-'Leg 6'!C21 -> 0.067951389 | E23: =VLOOKUP(B23,Registration!$B$3:$C$77,2,FALSE) -> 8 | F23: 4 | G23: =D23/11.1 -> 0.0061217467
A24: 21 | B24: 65 | C24: 0.39054398 | D24: =C24-'Leg 6'!C25 -> 0.054814815 | E24: =VLOOKUP(B24,Registration!$B$3:$C$77,2,FALSE) -> 10 | F24: 6 | G24: =D24/11.1 -> 0.0049382716
A25: 22 | B25: 46 | C25: 0.39159722 | D25: =C25-'Leg 6'!C26 -> 0.052974537 | E25: =VLOOKUP(B25,Registration!$B$3:$C$77,2,FALSE) -> 8 | F25: 5 | G25: =D25/11.1 -> 0.0047724808
A26: 23 | B26: 44 | C26: 0.39670139 | D26: =C26-'Leg 6'!C24 -> 0.064386574 | E26: =VLOOKUP(B26,Registration!$B$3:$C$77,2,FALSE) -> 8 | F26: 6 | G26: =D26/11.1 -> 0.0058005923
A27: 24 | B27: 30 | C27: 0.4012963 | D27: =C27-'Leg 6'!C27 -> 0.060324074 | E27: =VLOOKUP(B27,Registration!$B$3:$C$77,2,FALSE) -> 8 | F27: 7 | G27: =D27/11.1 -> 0.0054346013
A28: 25 | B28: 22 | C28: 0.40314815 | D28: =C28-'Leg 6'!C29 -> 0.059351852 | E28: =VLOOKUP(B28,Registration!$B$3:$C$77,2,FALSE) -> 7 | F28: 1 | G28: =D28/11.1 -> 0.0053470137
A29: 26 | B29: 56 | C29: 0.40400463 | D29: =C29-'Leg 6'!C28 -> 0.062314815 | E29: =VLOOKUP(B29,Registration!$B$3:$C$77,2,FALSE) -> 9 | F29: 2 | G29: =D29/11.1 -> 0.0056139473
A30: 27 | B30: 20 | C30: 0.40712963 | D30: =C30-'Leg 6'!C34 -> 0.054351852 | E30: =VLOOKUP(B30,Registration!$B$3:$C$77,2,FALSE) -> 6 | F30: 2 | G30: =D30/11.1 -> 0.0048965632
A31: 28 | B31: 57 | C31: 0.4087963 | D31: =C31-'Leg 6'!C30 -> 0.059085648 | E31: =VLOOKUP(B31,Registration!$B$3:$C$77,2,FALSE) -> 9 | F31: 3 | G31: =D31/11.1 -> 0.0053230314
A32: 29 | B32: 19 | C32: 0.41076389 | D32: =C32-'Leg 6'!C36 -> 0.056342593 | E32: =VLOOKUP(B32,Registration!$B$3:$C$77,2,FALSE) -> 6 | F32: 3 | G32: =D32/11.1 -> 0.0050759092
A33: 30 | B33: 29 | C33: 0.41094907 | D33: =C33-'Leg 6'!C33 -> 0.058645833 | E33: =VLOOKUP(B33,Registration!$B$3:$C$77,2,FALSE) -> 8 | F33: 8 | G33: =D33/11.1 -> 0.0052834084
A34: 31 | B34: 11 | C34: 0.41202546 | D34: =C34-'Leg 6'!C35 -> 0.0590625 | E34: =VLOOKUP(B34,Registration!$B$3:$C$77,2,FALSE) -> 3 | F34: 1 | G34: =D34/11.1 -> 0.0053209459
A35: 32 | B35: 61 | C35: 0.41304398 | D35: =C35-'Leg 6'!C31 -> 0.06287037 | E35: =VLOOKUP(B35,Registration!$B$3:$C$77,2,FALSE) -> 10 | F35: 7 | G35: =D35/11.1 -> 0.0056639973
A36: 33 | B36: 41 | C36: 0.41309028 | D36: =C36-'Leg 6'!C32 -> 0.062071759 | E36: =VLOOKUP(B36,Registration!$B$3:$C$77,2,FALSE) -> 8 | F36: 9 | G36: =D36/11.1 -> 0.0055920504
A37: 34 | B37: 10 | C37: 0.41763889 | D37: =C37-'Leg 6'!C39 -> 0.057118056 | E37: =VLOOKUP(B37,Registration!$B$3:$C$77,2,FALSE) -> 3 | F37: 2 | G37: =D37/11.1 -> 0.0051457708
A38: 35 | B38: 32 | C38: 0.41978009 | D38: =C38-'Leg 6'!C38 -> 0.064050926 | E38: =VLOOKUP(B38,Registration!$B$3:$C$77,2,FALSE) -> 8 | F38: 10 | G38: =D38/11.1 -> 0.0057703537
A39: 36 | B39: 31 | C39: 0.42445602 | D39: =C39-'Leg 6'!C37 -> 0.069571759 | E39: =VLOOKUP(B39,Registration!$B$3:$C$77,2,FALSE) -> 8 | F39: 11 | G39: =D39/11.1 -> 0.0062677261
A40: 37 | B40: 33 | C40: 0.42559028 | D40: =C40-'Leg 6'!C40 -> 0.057210648 | E40: =VLOOKUP(B40,Registration!$B$3:$C$77,2,FALSE) -> 8 | F40: 12 | G40: =D40/11.1 -> 0.0051541124
...
