Workbook

Sheet Registration
B1: 2018 Relay Race
A2: List | B2: Bib # | C2: Division | D2: Name
A3: 1 | B3: 1 | C3: Men's | D3: That's Fine Track Club
A4: 2 | B4: 2 | C4: Men's | D4: Back Bay Athletic Club | E4: DNS
A5: 3 | B5: 3 | C5: Men's | D5: Lancer Punch
A6: 4 | B6: 4 | C6: Men's | D6: Sol
A7: 5 | B7: 5 | C7: Men's | D7: Team Carpe Gluteus
A8: 6 | B8: 6 | C8: Men's | D8: The Esteemed Buns
A9: 7 | B9: 7 | C9: Men's | D9: The Extreme Falcons
A10: 8 | B10: 8 | C10: Men's | D10: West Valley Track Club 1
A11: 9 | B11: 9 | C11: Men's | D11: West Valley Track Club 2
A12: 10 | B12: 52 | C12: Men's | D12: The Midnight Society
A13: 11 | B13: 10 | C13: Men40+ | D13: West Valley Track Club Masters
A14: 12 | B14: 11 | C14: Men50+ | D14: Harey Tortuga
A15: 13 | B15: 12 | C15: Men50+ | D15: Original A Team
A16: 14 | B16: 13 | C16: Ultra | D16: Diego Diaz
... A20: 18 | B20: 19 | C20: Womens | D20: Sunnyside Striders
A21: 19 | B21: 20 | C21: Womens | D21: Wolfpack Ladies | E21: DNS
A22: 20 | B22: 21 | C22: Womens | D22: West Valley Track Club Womens
A23: 21 | B23: 22 | C23: Wmn 40+ | D23: Impala Racing Team
A24: 22 | B24: 23 | C24: Mixed | D24: Adventure is Out There
A25: 23 | B25: 24 | C25: Mixed | D25: Dances with Wolfpack
A26: 24 | B26: 25 | C26: Mixed | D26: Drinkers with a Running Problem
A27: 25 | B27: 26 | C27: Mixed | D27: Fleet Feet Sac - Blue
A28: 26 | B28: 27 | C28: Mixed | D28: Fleet Feet Sac - Orange
A29: 27 | B29: 28 | C29: Mixed | D29: GGRC - Runs N' Roses
A30: 28 | B30: 29 | C30: Mixed | D30: GGRC - Show Us What You Got
A31: 29 | B31: 30 | C31: Mixed | D31: GGRC - Snow White & The 7 Dwarfs
A32: 30 | B32: 31 | C32: Mixed | D32: GGRC - Speedsters
A33: 31 | B33: 32 | C33: Mixed | D33: Jocks and Jills
... A44: 42 | B44: 43 | C44: Mixed | D44: SF/East Bay Beer Runners
A45: 43 | B45: 44 | C45: Mixed | D45: Sheepdogs | E45: DNS
A46: 44 | B46: 45 | C46: Mixed | D46: Smok'n Oaks
A47: 45 | B47: 46 | C47: Mixed | D47: Sole Mates
A48: 46 | B48: 18 | C48: Mixed | D48: SRA Elite
A49: 47 | B49: 47 | C49: Mixed | D49: Tahoe Blue Crew
A50: 48 | B50: 48 | C50: Mixed | D50: Team Party Cat
A51: 49 | B51: 49 | C51: Mixed | D51: Team Pink
A52: 50 | B52: 50 | C52: Mixed | D52: That's Fine Too
A53: 51 | B53: 51 | C53: Mixed | D53: The Aches and Pains
...

Sheet Totals Sorted
G1: 2018 Decelle Tahoe Relay Race
C2: 9.4 Miles | E2: 13.1 Miles | G2: 9.6 miles | I2: 9.5 miles | K2: 10.7 Miles | M2: 8.6 Miles | O2: 10.5 Miles | Q2: Div.
A3: Bib # | B3: Div | C3: Leg 1 Time | D3: Leg 2 Cum | E3: Leg 2 Split | F3: Leg 3 Cum | G3: Leg 3 Split | H3: Leg 4 Cum | I3: Leg 4 Split | J3: Leg 5 Cum | K3: Leg 5 Split | L3: Leg 6 Cum | M3: Leg 6 Split | N3: Total Time | O3: Leg 7 Split | P3: Total Time | Q3: Place
A4: 1 | B4: =VLOOKUP(A4,Registration!$B$3:$C$77,2,FALSE) -> Men's | C4: 0.038668981 | D4: 0.092060185 | E4: =+D4-C4 -> 0.053391204 | F4: 0.12983796 | G4: =+F4-D4 -> 0.037777778 | H4: 0.16694444 | I4: =+H4-F4 -> 0.037106481 | J4: 0.20850694 | K4: =+J4-H4 -> 0.0415625 | L4: 0.24641204 | M4: =+L4-J4 -> 0.037905093 | N4: 0.2856713 | O4: =+N4-L4 -> 0.039259259 | P4: 0.2856713 | Q4: 1
A5: 8 | B5: =VLOOKUP(A5,Registration!$B$3:$C$77,2,FALSE) -> Men's | C5: 0.035810185 | D5: 0.092939815 | E5: =+D5-C5 -> 0.05712963 | F5: 0.13148148 | G5: =+F5-D5 -> 0.038541667 | H5: 0.16864583 | I5: =+H5-F5 -> 0.037164352 | J5: 0.21112269 | K5: =+J5-H5 -> 0.042476852 | L5: 0.25092593 | M5: =+L5-J5 -> 0.039803241 | N5: 0.28831019 | O5: =+N5-L5 -> 0.037384259 | P5: 0.28831019 | Q5: 2
A6: 3 | B6: =VLOOKUP(A6,Registration!$B$3:$C$77,2,FALSE) -> Men's | C6: 0.041180556 | D6: 0.095636574 | E6: =+D6-C6 -> 0.054456019 | F6: 0.13800926 | G6: =+F6-D6 -> 0.042372685 | H6: 0.18074074 | I6: =+H6-F6 -> 0.042731481 | J6: 0.22912037 | K6: =+J6-H6 -> 0.04837963 | L6: 0.26944444 | M6: =+L6-J6 -> 0.040324074 | N6: 0.31226852 | O6: =+N6-L6 -> 0.042824074 | P6: 0.31226852 | Q6: 3
A7: 9 | B7: =VLOOKUP(A7,Registration!$B$3:$C$77,2,FALSE) -> Men's | C7: 0.039814815 | D7: 0.095613426 | E7: =+D7-C7 -> 0.055798611 | F7: 0.13905093 | G7: =+F7-D7 -> 0.0434375 | H7: 0.18525463 | I7: =+H7-F7 -> 0.046203704 | J7: 0.23431713 | K7: =+J7-H7 -> 0.0490625 | L7: 0.27340278 | M7: =+L7-J7 -> 0.039085648 | N7: 0.31905093 | O7: =+N7-L7 -> 0.045648148 | P7: 0.31905093 | Q7: 4
A8: 6 | B8: =VLOOKUP(A8,Registration!$B$3:$C$77,2,FALSE) -> Men's | C8: 0.040104167 | D8: 0.10967593 | E8: =+D8-C8 -> 0.069571759 | F8: 0.1502662 | G8: =+F8-D8 -> 0.040590278 | H8: 0.2008912 | I8: =+H8-F8 -> 0.050625 | J8: 0.25356481 | K8: =+J8-H8 -> 0.052673611 | L8: 0.30778935 | M8: =+L8-J8 -> 0.054224537 | N8: 0.35607639 | O8: =+N8-L8 -> 0.048287037 | P8: 0.35607639 | Q8: 5
A9: 52 | B9: =VLOOKUP(A9,Registration!$B$3:$C$77,2,FALSE) -> Men's | C9: 0.049525463 | D9: 0.10993056 | E9: =+D9-C9 -> 0.060405093 | F9: 0.16957176 | G9: =+F9-D9 -> 0.059641204 | H9: 0.21902778 | I9: =+H9-F9 -> 0.049456019 | J9: 0.27371528 | K9: =+J9-H9 -> 0.0546875 | L9: 0.32253472 | M9: =+L9-J9 -> 0.048819444 | N9: 0.36814815 | O9: =+N9-L9 -> 0.045613426 | P9: 0.36814815 | Q9: 6
A10: 4 | B10: =VLOOKUP(A10,Registration!$B$3:$C$77,2,FALSE) -> Men's | C10: 0.052986111 | D10: 0.13472222 | E10: =+D10-C10 -> 0.081736111 | H10: 0.25039352 | I10: =+H10-F10 -> 0.25039352 | L10: 0.38075231 | N10: 0.4480787 | O10: =+N10-L10 -> 0.067326389 | P10: 0.4480787 | Q10: 7
A11: 7 | B11: =VLOOKUP(A11,Registration!$B$3:$C$77,2,FALSE) -> Men's | C11: 0.060694444 | D11: 0.15577546 | E11: =+D11-C11 -> 0.095081019 | F11: 0.21635417 | G11: =+F11-D11 -> 0.060578704 | H11: 0.28451389 | I11: =+H11-F11 -> 0.068159722 | J11: 0.35121528 | K11: =+J11-H11 -> 0.066701389 | L11: 0.40960648 | M11: =+L11-J11 -> 0.058391204 | N11: 0.48060185 | O11: =+N11-L11 -> 0.07099537 | P11: 0.48060185 | Q11: 8
A12: 5 | B12: =VLOOKUP(A12,Registration!$B$3:$C$77,2,FALSE) -> Men's | C12: 0.073761574 | D12: 0.15643519 | E12: =+D12-C12 -> 0.082673611 | F12: 0.21969907 | G12: =+F12-D12 -> 0.063263889 | H12: 0.29878472 | I12: =+H12-F12 -> 0.079085648 | J12: 0.36528935 | K12: =+J12-H12 -> 0.06650463 | L12: 0.41709491 | M12: =+L12-J12 -> 0.051805556 | N12: 0.48466435 | O12: =+N12-L12 -> 0.067569444 | P12: 0.48466435 | Q12: 9
A13: 10 | B13: =VLOOKUP(A13,Registration!$B$3:$C$77,2,FALSE) -> Men40+ | C13: 0.040428241 | D13: 0.10359954 | E13: =+D13-C13 -> 0.063171296 | F13: 0.14491898 | G13: =+F13-D13 -> 0.041319444 | H13: 0.18888889 | I13: =+H13-F13 -> 0.043969907 | J13: 0.23578704 | K13: =+J13-H13 -> 0.046898148 | L13: 0.27435185 | M13: =+L13-J13 -> 0.038564815 | N13: 0.31982639 | O13: =+N13-L13 -> 0.045474537 | P13: 0.31982639 | Q13: 1
A14: 12 | B14: =VLOOKUP(A14,Registration!$B$3:$C$77,2,FALSE) -> Men50+ | C14: 0.053587963 | D14: 0.12387731 | E14: =+D14-C14 -> 0.070289352 | F14: 0.18269676 | G14: =+F14-D14 -> 0.058819444 | H14: 0.23659722 | I14: =+H14-F14 -> 0.053900463 | J14: 0.29834491 | K14: =+J14-H14 -> 0.061747685 | L14: 0.34597222 | M14: =+L14-J14 -> 0.047627315 | N14: 0.4053125 | O14: =+N14-L14 -> 0.059340278 | P14: 0.4053125 | Q14: 1
A15: 11 | B15: =VLOOKUP(A15,Registration!$B$3:$C$77,2,FALSE) -> Men50+ | C15: 0.0528125 | D15: 0.12914352 | E15: =+D15-C15 -> 0.076331019 | F15: 0.18417824 | G15: =+F15-D15 -> 0.055034722 | H15: 0.24055556 | I15: =+H15-F15 -> 0.056377315 | J15: 0.30065972 | K15: =+J15-H15 -> 0.060104167 | L15: 0.35335648 | M15: =+L15-J15 -> 0.052696759 | N15: 0.40814815 | O15: =+N15-L15 -> 0.054791667 | P15: 0.40814815 | Q15: 2
A16: 13 | B16: Ultra | D16: 0.12777778 | F16: 0.18565972 | G16: =+F16-D16 -> 0.057881944 | H16: 0.24809028 | I16: =+H16-F16 -> 0.062430556 | J16: 0.32709491 | K16: =+J16-H16 -> 0.07900463 | L16: 0.39461806 | M16: =+L16-J16 -> 0.067523148 | N16: 0.47016204 | O16: =+N16-L16 -> 0.075543981 | P16: 0.47016204 | Q16: 1
A17: 18 | B17: =VLOOKUP(A17,Registration!$B$3:$C$77,2,FALSE) -> Mixed | C17: 0.042048611 | D17: 0.10148148 | E17: =+D17-C17 -> 0.05943287 | F17: 0.14891204 | G17: =+F17-D17 -> 0.047430556 | H17: 0.19232639 | I17: =+H17-F17 -> 0.043414352 | J17: 0.24011574 | K17: =+J17-H17 -> 0.047789352 | L17: 0.28103009 | M17: =+L17-J17 -> 0.040914352 | N17: 0.33082176 | O17: =+N17-L17 -> 0.049791667 | P17: 0.33082176 | Q17: 1
A18: 50 | B18: =VLOOKUP(A18,Registration!$B$3:$C$77,2,FALSE) -> Mixed | C18: 0.045648148 | D18: 0.11306713 | E18: =+D18-C18 -> 0.067418981 | F18: 0.16291667 | G18: =+F18-D18 -> 0.049849537 | H18: 0.20570602 | I18: =+H18-F18 -> 0.042789352 | J18: 0.25892361 | K18: =+J18-H18 -> 0.053217593 | L18: 0.30311343 | M18: =+L18-J18 -> 0.044189815 | N18: 0.35268519 | O18: =+N18-L18 -> 0.049571759 | P18: 0.35268519 | Q18: 2
A19: 37 | B19: =VLOOKUP(A19,Registration!$B$3:$C$77,2,FALSE) -> Mixed | C19: 0.057465278 | D19: 0.11680556 | E19: =+D19-C19 -> 0.059340278 | F19: 0.16746528 | G19: =+F19-D19 -> 0.050659722 | H19: 0.21376157 | I19: =+H19-F19 -> 0.046296296 | J19: 0.31840278 | K19: =+J19-H19 -> 0.1046412 | L19: 0.35631944 | M19: =+L19-J19 -> 0.037916667 | N19: 0.37107639 | O19: =+N19-L19 -> 0.014756944 | P19: 0.37107639 | Q19: 3
A20: 26 | B20: =VLOOKUP(A20,Registration!$B$3:$C$77,2,FALSE) -> Mixed | C20: 0.043298611 | D20: 0.11496528 | E20: =+D20-C20 -> 0.071666667 | F20: 0.16376157 | G20: =+F20-D20 -> 0.048796296 | H20: 0.21434028 | I20: =+H20-F20 -> 0.050578704 | J20: 0.27571759 | K20: =+J20-H20 -> 0.061377315 | L20: 0.32079861 | M20: =+L20-J20 -> 0.045081019 | N20: 0.37240741 | O20: =+N20-L20 -> 0.051608796 | P20: 0.37240741 | Q20: 4
A21: 43 | B21: =VLOOKUP(A21,Registration!$B$3:$C$77,2,FALSE) -> Mixed | C21: 0.046921296 | D21: 0.1190625 | E21: =+D21-C21 -> 0.072141204 | F21: 0.170625 | G21: =+F21-D21 -> 0.0515625 | H21: 0.22201389 | I21: =+H21-F21 -> 0.051388889 | J21: 0.28664352 | K21: =+J21-H21 -> 0.06462963 | L21: 0.33872685 | M21: =+L21-J21 -> 0.052083333 | N21: 0.39034722 | O21: =+N21-L21 -> 0.05162037 | P21: 0.39034722 | Q21: 5
A22: 25 | B22: =VLOOKUP(A22,Registration!$B$3:$C$77,2,FALSE) -> Mixed | C22: 0.05056713 | D22: 0.11482639 | E22: =+D22-C22 -> 0.064259259 | F22: 0.17090278 | G22: =+F22-D22 -> 0.056076389 | H22: 0.22849537 | I22: =+H22-F22 -> 0.057592593 | J22: 0.2840625 | K22: =+J22-H22 -> 0.05556713 | L22: 0.32769676 | M22: =+L22-J22 -> 0.043634259 | N22: 0.39737269 | O22: =+N22-L22 -> 0.069675926 | P22: 0.39737269 | Q22: 6
A23: 24 | B23: =VLOOKUP(A23,Registration!$B$3:$C$77,2,FALSE) -> Mixed | C23: 0.045543981 | D23: 0.11920139 | E23: =+D23-C23 -> 0.073657407 | F23: 0.17459491 | G23: =+F23-D23 -> 0.055393519 | H23: 0.23138889 | I23: =+H23-F23 -> 0.056793981 | J23: 0.29696759 | K23: =+J23-H23 -> 0.065578704 | L23: 0.34356481 | M23: =+L23-J23 -> 0.046597222 | N23: 0.39759259 | O23: =+N23-L23 -> 0.054027778 | P23: 0.39759259 | Q23: 7
A24: 35 | B24: =VLOOKUP(A24,Registration!$B$3:$C$77,2,FALSE) -> Mixed | C24: 0.051805556 | D24: 0.12461806 | E24: =+D24-C24 -> 0.0728125 | F24: 0.18027778 | G24: =+F24-D24 -> 0.055659722 | H24: 0.23408565 | I24: =+H24-F24 -> 0.05380787 | J24: 0.30054398 | K24: =+J24-H24 -> 0.066458333 | L24: 0.35234954 | M24: =+L24-J24 -> 0.051805556 | N24: 0.40371528 | O24: =+N24-L24 -> 0.051365741 | P24: 0.40371528 | Q24: 8
A25: 39 | B25: =VLOOKUP(A25,Registration!$B$3:$C$77,2,FALSE) -> Mixed | C25: 0.059606481 | D25: 0.13903935 | E25: =+D25-C25 -> 0.07943287 | F25: 0.19451389 | G25: =+F25-D25 -> 0.055474537 | H25: 0.24859954 | I25: =+H25-F25 -> 0.054085648 | J25: 0.30733796 | K25: =+J25-H25 -> 0.058738426 | L25: 0.34739583 | M25: =+L25-J25 -> 0.04005787 | N25: 0.40445602 | O25: =+N25-L25 -> 0.057060185 | P25: 0.40445602 | Q25: 9
A26: 34 | B26: =VLOOKUP(A26,Registration!$B$3:$C$77,2,FALSE) -> Mixed | C26: 0.055081019 | D26: 0.13002315 | E26: =+D26-C26 -> 0.07494213 | F26: 0.19055556 | G26: =+F26-D26 -> 0.060532407 | H26: 0.24581019 | I26: =+H26-F26 -> 0.05525463 | J26: 0.30585648 | K26: =+J26-H26 -> 0.060046296 | L26: 0.35538194 | M26: =+L26-J26 -> 0.049525463 | N26: 0.40865741 | O26: =+N26-L26 -> 0.053275463 | P26: 0.40865741 | Q26: 10
A27: 31 | B27: =VLOOKUP(A27,Registration!$B$3:$C$77,2,FALSE) -> Mixed | C27: 0.0646875 | D27: 0.1306713 | E27: =+D27-C27 -> 0.065983796 | F27: 0.18873843 | G27: =+F27-D27 -> 0.05806713 | H27: 0.24127315 | I27: =+H27-F27 -> 0.052534722 | J27: 0.30287037 | K27: =+J27-H27 -> 0.061597222 | L27: 0.34802083 | M27: =+L27-J27 -> 0.045150463 | N27: 0.4112037 | O27: =+N27-L27 -> 0.06318287 | P27: 0.4112037 | Q27: 11
A28: 28 | B28: =VLOOKUP(A28,Registration!$B$3:$C$77,2,FALSE) -> Mixed | C28: 0.061215278 | D28: 0.12796296 | E28: =+D28-C28 -> 0.066747685 | F28: 0.19556713 | G28: =+F28-D28 -> 0.067604167 | H28: 0.25034722 | I28: =+H28-F28 -> 0.054780093 | J28: 0.3178125 | K28: =+J28-H28 -> 0.067465278 | L28: 0.36467593 | M28: =+L28-J28 -> 0.046863426 | N28: 0.4125 | O28: =+N28-L28 -> 0.047824074 | P28: 0.4125 | Q28: 12
... A36: 49 | B36: =VLOOKUP(A36,Registration!$B$3:$C$77,2,FALSE) -> Mixed | C36: 0.062326389 | D36: 0.13677083 | E36: =+D36-C36 -> 0.074444444 | F36: 0.20179398 | G36: =+F36-D36 -> 0.065023148 | H36: 0.26581019 | I36: =+H36-F36 -> 0.064016204 | J36: 0.33175926 | K36: =+J36-H36 -> 0.065949074 | L36: 0.38436343 | M36: =+L36-J36 -> 0.052604167 | N36: 0.45100694 | O36: =+N36-L36 -> 0.066643519 | P36: 0.45100694 | Q36: 20
A37: 42 | B37: Mixed | D37: 0.13584491 | F37: 0.20208333 | G37: =+F37-D37 -> 0.066238426 | H37: 0.26381944 | I37: =+H37-F37 -> 0.061736111 | J37: 0.33885417 | K37: =+J37-H37 -> 0.075034722 | L37: 0.39230324 | M37: =+L37-J37 -> 0.053449074 | N37: 0.45202546 | O37: =+N37-L37 -> 0.059722222 | P37: 0.45202546 | Q37: 21
A38: 47 | B38: Mixed | D38: 0.1424537 | F38: 0.20575231 | G38: =+F38-D38 -> 0.063298611 | H38: 0.26880787 | I38: =+H38-F38 -> 0.063055556 | J38: 0.31765046 | K38: =+J38-H38 -> 0.048842593 | L38: 0.41165509 | M38: =+L38-J38 -> 0.09400463 | N38: 0.46849537 | O38: =+N38-L38 -> 0.056840278 | P38: 0.46849537 | Q38: 22
A39: 51 | B39: Mixed | D39: 0.16986111 | F39: 0.23021991 | G39: =+F39-D39 -> 0.060358796 | H39: 0.30118056 | I39: =+H39-F39 -> 0.070960648 | J39: 0.37986111 | K39: =+J39-H39 -> 0.078680556 | L39: 0.43902778 | M39: =+L39-J39 -> 0.059166667 | N39: 0.47302083 | O39: =+N39-L39 -> 0.033993056 | P39: 0.47302083 | Q39: 23
A40: 23 | B40: =VLOOKUP(A40,Registration!$B$3:$C$77,2,FALSE) -> Mixed | C40: 0.071226852 | D40: 0.15084491 | E40: =+D40-C40 -> 0.079618056 | F40: 0.2094213 | G40: =+F40-D40 -> 0.058576389 | H40: 0.27050926 | I40: =+H40-F40 -> 0.061087963 | J40: 0.34993056 | K40: =+J40-H40 -> 0.079421296 | L40: 0.41612269 | M40: =+L40-J40 -> 0.06619213 | N40: 0.48709491 | O40: =+N40-L40 -> 0.070972222 | P40: 0.48709491 | Q40: 24
A41: 41 | B41: =VLOOKUP(A41,Registration!$B$3:$C$77,2,FALSE) -> Mixed | C41: 0.078020833 | D41: 0.15630787 | E41: =+D41-C41 -> 0.078287037 | F41: 0.2275 | G41: =+F41-D41 -> 0.07119213 | H41: 0.29915509 | I41: =+H41-F41 -> 0.071655093 | J41: 0.37137731 | K41: =+J41-H41 -> 0.072222222 | L41: 0.41763889 | M41: =+L41-J41 -> 0.046261574 | N41: 0.48883102 | O41: =+N41-L41 -> 0.07119213 | P41: 0.48883102 | Q41: 25
A42: 46 | B42: =VLOOKUP(A42,Registration!$B$3:$C$77,2,FALSE) -> Mixed | C42: 0.073981481 | D42: 0.15408565 | E42: =+D42-C42 -> 0.080104167 | F42: 0.22792824 | G42: =+F42-D42 -> 0.073842593 | H42: 0.29255787 | I42: =+H42-F42 -> 0.06462963 | J42: 0.36991898 | K42: =+J42-H42 -> 0.077361111 | L42: 0.41939815 | M42: =+L42-J42 -> 0.049479167 | N42: 0.50215278 | O42: =+N42-L42 -> 0.08275463 | P42: 0.50215278 | Q42: 26
A43: 48 | B43: =VLOOKUP(A43,Registration!$B$3:$C$77,2,FALSE) -> Mixed | C43: 0.060972222 | D43: 0.1628125 | E43: =+D43-C43 -> 0.10184028 | F43: 0.22287037 | G43: =+F43-D43 -> 0.06005787 | H43: 0.29211806 | I43: =+H43-F43 -> 0.069247685 | J43: 0.37899306 | K43: =+J43-H43 -> 0.086875 | L43: 0.43408565 | M43: =+L43-J43 -> 0.055092593 | N43: 0.51268519 | O43: =+N43-L43 -> 0.078599537 | P43: 0.51268519 | Q43: 27
A44: 40 | B44: =VLOOKUP(A44,Registration!$B$3:$C$77,2,FALSE) -> Mixed | C44: 0.066261574 | D44: 0.1606713 | E44: =+D44-C44 -> 0.094409722 | F44: 0.22989583 | G44: =+F44-D44 -> 0.069224537 | H44: 0.30186343 | I44: =+H44-F44 -> 0.071967593 | J44: 0.39393519 | K44: =+J44-H44 -> 0.092071759 | L44: 0.45096065 | M44: =+L44-J44 -> 0.057025463 | N44: 0.52483796 | O44: =+N44-L44 -> 0.073877315 | P44: 0.52483796 | Q44: 28
A45: 22 | B45: =VLOOKUP(A45,Registration!$B$3:$C$77,2,FALSE) -> Wmn 40+ | C45: 0.0515625 | D45: 0.11746528 | E45: =+D45-C45 -> 0.065902778 | F45: 0.16841435 | G45: =+F45-D45 -> 0.050949074 | H45: 0.2252662 | I45: =+H45-F45 -> 0.056851852 | J45: 0.28670139 | K45: =+J45-H45 -> 0.061435185 | L45: 0.33679398 | M45: =+L45-J45 -> 0.050092593 | N45: 0.39130787 | O45: =+N45-L45 -> 0.054513889 | P45: 0.39130787 | Q45: 1
A46: 16 | B46: =VLOOKUP(A46,Registration!$B$3:$C$77,2,FALSE) -> Womens | C46: 0.049525463 | D46: 0.10986111 | E46: =+D46-C46 -> 0.060335648 | F46: 0.1575463 | G46: =+F46-D46 -> 0.047685185 | H46: 0.20423611 | I46: =+H46-F46 -> 0.046689815 | J46: 0.25356481 | K46: =+J46-H46 -> 0.049328704 | L46: 0.3 | M46: =+L46-J46 -> 0.046435185 | N46: 0.35038194 | O46: =+N46-L46 -> 0.050381944 | P46: 0.35038194 | Q46: 1
A47: 21 | B47: =VLOOKUP(A47,Registration!$B$3:$C$77,2,FALSE) -> Womens | C47: 0.050902778 | D47: 0.11521991 | E47: =+D47-C47 -> 0.06431713 | F47: 0.15990741 | G47: =+F47-D47 -> 0.0446875 | H47: 0.20744213 | I47: =+H47-F47 -> 0.047534722 | J47: 0.26197917 | K47: =+J47-H47 -> 0.054537037 | L47: 0.3149537 | M47: =+L47-J47 -> 0.052974537 | N47: 0.36546296 | O47: =+N47-L47 -> 0.050509259 | P47: 0.36546296 | Q47: 2
...

Sheet Div Sorted Results
A1: Sorted Results
B2: 2018 Tahoe Relay
A4: Overall Place | B4: Bib # | C4: Total Time | D4: Div | E4: Div Place | F4: Pace
A5: 1 | D5: =VLOOKUP(B5,Registration!$B$3:$C$77,2,FALSE) -> #N/A | F5: =C5/72 -> 0
A6: 2 | D6: =VLOOKUP(B6,Registration!$B$3:$C$77,2,FALSE) -> #N/A | F6: =C6/72 -> 0
A7: 3 | D7: =VLOOKUP(B7,Registration!$B$3:$C$77,2,FALSE) -> #N/A | F7: =C7/72 -> 0
A8: 4 | D8: =VLOOKUP(B8,Registration!$B$3:$C$77,2,FALSE) -> #N/A | F8: =C8/72 -> 0
A9: 5 | D9: =VLOOKUP(B9,Registration!$B$3:$C$77,2,FALSE) -> #N/A | F9: =C9/72 -> 0
A10: 6 | D10: =VLOOKUP(B10,Registration!$B$3:$C$77,2,FALSE) -> #N/A | F10: =C10/72 -> 0
A11: 7 | D11: =VLOOKUP(B11,Registration!$B$3:$C$77,2,FALSE) -> #N/A | F11: =C11/72 -> 0
A12: 8 | D12: =VLOOKUP(B12,Registration!$B$3:$C$77,2,FALSE) -> #N/A | F12: =C12/72 -> 0
A13: 9 | D13: =VLOOKUP(B13,Registration!$B$3:$C$77,2,FALSE) -> #N/A | F13: =C13/72 -> 0
A14: 10 | D14: =VLOOKUP(B14,Registration!$B$3:$C$77,2,FALSE) -> #N/A | F14: =C14/72 -> 0
A15: 11 | D15: =VLOOKUP(B15,Registration!$B$3:$C$77,2,FALSE) -> #N/A | F15: =C15/72 -> 0
A16: 12 | D16: =VLOOKUP(B16,Registration!$B$3:$C$77,2,FALSE) -> #N/A | F16: =C16/72 -> 0
... A78: 74 | D78: =VLOOKUP(B78,Registration!$B$3:$C$77,2,FALSE) -> #N/A | F78: =C78/72 -> 0

Sheet Leg 1
A1: Leg 1 | B1: 2018
F2: 9.4 Miles
A3: Place | B3: Bib # | C3: Leg Time | D3: Div | E3: Div Place | F3: Pace
A4: 2 | B4: 1 | C4: 0.038668981 | D4: =VLOOKUP(B4,Registration!$B$3:$C$77,2,FALSE) -> Men's | F4: =C4/8.6 -> 0.0044963932
A5: 7 | B5: 3 | C5: 0.041180556 | D5: =VLOOKUP(B5,Registration!$B$3:$C$77,2,FALSE) -> Men's | F5: =C5/8.6 -> 0.0047884367
A6: 28 | B6: 4 | C6: 0.052986111 | D6: =VLOOKUP(B6,Registration!$B$3:$C$77,2,FALSE) -> Men's | F6: =C6/8.6 -> 0.0061611757
A7: 56 | B7: 5 | C7: 0.073761574 | D7: =VLOOKUP(B7,Registration!$B$3:$C$77,2,FALSE) -> Men's | F7: =C7/8.6 -> 0.0085769272
A8: 5 | B8: 6 | C8: 0.040104167 | D8: =VLOOKUP(B8,Registration!$B$3:$C$77,2,FALSE) -> Men's | F8: =C8/8.6 -> 0.0046632752
A9: 39 | B9: 7 | C9: 0.060694444 | D9: =VLOOKUP(B9,Registration!$B$3:$C$77,2,FALSE) -> Men's | F9: =C9/8.6 -> 0.0070574935
A10: 1 | B10: 8 | C10: 0.035810185 | D10: =VLOOKUP(B10,Registration!$B$3:$C$77,2,FALSE) -> Men's | F10: =C10/8.6 -> 0.004163975
A11: 4 | B11: 9 | C11: 0.039814815 | D11: =VLOOKUP(B11,Registration!$B$3:$C$77,2,FALSE) -> Men's | F11: =C11/8.6 -> 0.0046296296
A12: 6 | B12: 10 | C12: 0.040428241 | D12: =VLOOKUP(B12,Registration!$B$3:$C$77,2,FALSE) -> Men40+ | F12: =C12/8.6 -> 0.0047009582
A13: 26 | B13: 11 | C13: 0.0528125 | D13: =VLOOKUP(B13,Registration!$B$3:$C$77,2,FALSE) -> Men50+ | F13: =C13/8.6 -> 0.0061409884
A14: 29 | B14: 12 | C14: 0.053587963 | D14: =VLOOKUP(B14,Registration!$B$3:$C$77,2,FALSE) -> Men50+ | F14: =C14/8.6 -> 0.0062311585
A15: 19 | B15: 16 | C15: 0.049525463 | D15: =VLOOKUP(B15,Registration!$B$3:$C$77,2,FALSE) -> Womens | F15: =C15/8.6 -> 0.0057587748
... A64: 3 | B64: 73 | C64: 0.039259259 | D64: =VLOOKUP(B64,Registration!$B$3:$C$77,2,FALSE) -> HS-Boys | F64: =C64/8.6 -> 0.0045650301
A65: 62 | D65: =VLOOKUP(B65,Registration!$B$3:$C$77,2,FALSE) -> #N/A | F65: =C65/8.6 -> 0
A66: 63 | D66: =VLOOKUP(B66,Registration!$B$3:$C$77,2,FALSE) -> #N/A | F66: =C66/8.6 -> 0
A67: 64 | D67: =VLOOKUP(B67,Registration!$B$3:$C$77,2,FALSE) -> #N/A | F67: =C67/8.6 -> 0
A68: 65 | D68: =VLOOKUP(B68,Registration!$B$3:$C$77,2,FALSE) -> #N/A | F68: =C68/8.6 -> 0
A69: 66 | D69: =VLOOKUP(B69,Registration!$B$3:$C$77,2,FALSE) -> #N/A | F69: =C69/8.6 -> 0
A70: 67 | D70: =VLOOKUP(B70,Registration!$B$3:$C$77,2,FALSE) -> #N/A | F70: =C70/8.6 -> 0
A71: 68 | D71: =VLOOKUP(B71,Registration!$B$3:$C$77,2,FALSE) -> #N/A | F71: =C71/8.6 -> 0
A72: 69 | D72: =VLOOKUP(B72,Registration!$B$3:$C$77,2,FALSE) -> #N/A | F72: =C72/8.6 -> 0
A73: 70 | D73: =VLOOKUP(B73,Registration!$B$3:$C$77,2,FALSE) -> #N/A | F73: =C73/8.6 -> 0
A74: 71 | D74: =VLOOKUP(B74,Registration!$B$3:$C$77,2,FALSE) -> #N/A | F74: =C74/8.6 -> 0
A75: 72 | D75: =VLOOKUP(B75,Registration!$B$3:$C$77,2,FALSE) -> #N/A | F75: =C75/8.6 -> 0
A76: 73 | D76: =VLOOKUP(B76,Registration!$B$3:$C$77,2,FALSE) -> #N/A | F76: =C76/8.6 -> 0
A77: 74 | D77: =VLOOKUP(B77,Registration!$B$3:$C$77,2,FALSE) -> #N/A | F77: =C77/8.6 -> 0
I80: 5:30 start
I81: 13
I82: 14
I83: 51
I85: 5:50 start
I86: 17
I88: 6:00 start
I89: 5
I90: 23
I91: 40
I92: 41
...

Sheet leg 2
A1: Leg 2 | B1: 2018 Tahoe Relay
F2: 13.1 Miles
A3: Place | B3: Bib # | C3: Total Time | D3: Leg Time | E3: Div | F3: Pace
A4: 1 | B4: 1 | C4: 0.092060185 | D4: ='leg 2'!C4-'Leg 1'!C4 -> 0.053391204 | E4: =VLOOKUP(B4,Registration!$B$3:$C$77,2,FALSE) -> Men's | F4: =D4/13.1 -> 0.0040756644
A5: 2 | B5: 3 | C5: 0.095636574 | D5: ='leg 2'!C7-'Leg 1'!C7 -> 0.082673611 | E5: =VLOOKUP(B5,Registration!$B$3:$C$77,2,FALSE) -> Men's | F5: =D5/13.1 -> 0.0063109627
A6: 3 | B6: 4 | C6: 0.13472222 | D6: ='leg 2'!C42-'Leg 1'!C42 -> 0.058090278 | E6: =VLOOKUP(B6,Registration!$B$3:$C$77,2,FALSE) -> Men's | F6: =D6/13.1 -> 0.0044343723
A7: 4 | B7: 5 | C7: 0.15643519 | D7: ='leg 2'!C63-'Leg 1'!C63 -> 0.093969907 | E7: =VLOOKUP(B7,Registration!$B$3:$C$77,2,FALSE) -> Men's | F7: =D7/13.1 -> 0.0071732754
A8: 5 | B8: 6 | C8: 0.10967593 | D8: ='leg 2'!C12-'Leg 1'!C12 -> 0.063171296 | E8: =VLOOKUP(B8,Registration!$B$3:$C$77,2,FALSE) -> Men's | F8: =D8/13.1 -> 0.0048222364
A9: 6 | B9: 7 | C9: 0.15577546 | D9: ='leg 2'!C61-'Leg 1'!C61 -> 0.085150463 | E9: =VLOOKUP(B9,Registration!$B$3:$C$77,2,FALSE) -> Men's | F9: =D9/13.1 -> 0.0065000353
A10: 7 | B10: 8 | C10: 0.092939815 | D10: ='leg 2'!C5-'Leg 1'!C5 -> 0.054456019 | E10: =VLOOKUP(B10,Registration!$B$3:$C$77,2,FALSE) -> Men's | F10: =D10/13.1 -> 0.004156948
A11: 8 | B11: 9 | C11: 0.095613426 | D11: ='leg 2'!C6-'Leg 1'!C6 -> 0.081736111 | E11: =VLOOKUP(B11,Registration!$B$3:$C$77,2,FALSE) -> Men's | F11: =D11/13.1 -> 0.0062393978
A12: 9 | B12: 10 | C12: 0.10359954 | D12: ='leg 2'!C10-'Leg 1'!C10 -> 0.05712963 | E12: =VLOOKUP(B12,Registration!$B$3:$C$77,2,FALSE) -> Men40+ | F12: =D12/13.1 -> 0.0043610404
A13: 10 | B13: 11 | C13: 0.12914352 | D13: ='leg 2'!C35-'Leg 1'!C35 -> 0.07755787 | E13: =VLOOKUP(B13,Registration!$B$3:$C$77,2,FALSE) -> Men50+ | F13: =D13/13.1 -> 0.0059204481
A14: 11 | B14: 12 | C14: 0.12387731 | D14: ='leg 2'!C29-'Leg 1'!C29 -> 0.081608796 | E14: =VLOOKUP(B14,Registration!$B$3:$C$77,2,FALSE) -> Men50+ | F14: =D14/13.1 -> 0.0062296791
A15: 12 | B15: 13 | C15: 0.12777778 | D15: ='leg 2'!C32-'Leg 1'!C32 -> 0.085636574 | E15: =VLOOKUP(B15,Registration!$B$3:$C$77,2,FALSE) -> Ultra | F15: =D15/13.1 -> 0.0065371431
A16: 13 | B16: 14 | C16: 0.15782407 | D16: ='leg 2'!C64-'Leg 1'!C64 -> 0.13792824 | E16: =VLOOKUP(B16,Registration!$B$3:$C$77,2,FALSE) -> Womens | F16: =D16/13.1 -> 0.010528873
A17: 14 | B17: 16 | C17: 0.10986111 | D17: ='leg 2'!C13-'Leg 1'!C13 -> 0.076331019 | E17: =VLOOKUP(B17,Registration!$B$3:$C$77,2,FALSE) -> Womens | F17: =D17/13.1 -> 0.0058267953
A18: 15 | B18: 17 | C18: 0.15065972 | D18: ='leg 2'!C58-'Leg 1'!C58 -> 0.061435185 | E18: =VLOOKUP(B18,Registration!$B$3:$C$77,2,FALSE) -> Womens | F18: =D18/13.1 -> 0.0046897088
A19: 16 | B19: 18 | C19: 0.10148148 | D19: ='leg 2'!C9-'Leg 1'!C9 -> 0.095081019 | E19: =VLOOKUP(B19,Registration!$B$3:$C$77,2,FALSE) -> Mixed | F19: =D19/13.1 -> 0.007258093
A20: 17 | B20: 19 | C20: 0.12822917 | D20: ='leg 2'!C34-'Leg 1'!C34 -> 0.067152778 | E20: =VLOOKUP(B20,Registration!$B$3:$C$77,2,FALSE) -> Womens | F20: =D20/13.1 -> 0.0051261662
A21: 18 | B21: 21 | C21: 0.11521991 | D21: ='leg 2'!C20-'Leg 1'!C20 -> 0.076666667 | E21: =VLOOKUP(B21,Registration!$B$3:$C$77,2,FALSE) -> Womens | F21: =D21/13.1 -> 0.0058524173
A22: 19 | B22: 22 | C22: 0.11746528 | D22: ='leg 2'!C24-'Leg 1'!C24 -> 0.075902778 | E22: =VLOOKUP(B22,Registration!$B$3:$C$77,2,FALSE) -> Wmn 40+ | F22: =D22/13.1 -> 0.0057941052
A23: 20 | B23: 23 | C23: 0.15084491 | D23: ='leg 2'!C59-'Leg 1'!C59 -> 0.078645833 | E23: =VLOOKUP(B23,Registration!$B$3:$C$77,2,FALSE) -> Mixed | F23: =D23/13.1 -> 0.0060034987
A24: 21 | B24: 24 | C24: 0.11920139 | D24: ='leg 2'!C27-'Leg 1'!C27 -> 0.067222222 | E24: =VLOOKUP(B24,Registration!$B$3:$C$77,2,FALSE) -> Mixed | F24: =D24/13.1 -> 0.0051314673
A25: 22 | B25: 25 | C25: 0.11482639 | D25: ='leg 2'!C18-'Leg 1'!C18 -> 0.092962963 | E25: =VLOOKUP(B25,Registration!$B$3:$C$77,2,FALSE) -> Mixed | F25: =D25/13.1 -> 0.0070964094
A26: 23 | B26: 26 | C26: 0.11496528 | D26: ='leg 2'!C19-'Leg 1'!C19 -> 0.050578704 | E26: =VLOOKUP(B26,Registration!$B$3:$C$77,2,FALSE) -> Mixed | F26: =D26/13.1 -> 0.0038609697
A27: 24 | B27: 27 | C27: 0.13978009 | D27: ='leg 2'!C51-'Leg 1'!C51 -> 0.1244213 | E27: =VLOOKUP(B27,Registration!$B$3:$C$77,2,FALSE) -> Mixed | F27: =D27/13.1 -> 0.0094978089
A28: 25 | B28: 28 | C28: 0.12796296 | D28: ='leg 2'!C33-'Leg 1'!C33 -> 0.077118056 | E28: =VLOOKUP(B28,Registration!$B$3:$C$77,2,FALSE) -> Mixed | F28: =D28/13.1 -> 0.0058868745
A29: 26 | B29: 29 | C29: 0.1462963 | D29: ='leg 2'!C57-'Leg 1'!C57 -> 0.047523148 | E29: =VLOOKUP(B29,Registration!$B$3:$C$77,2,FALSE) -> Mixed | F29: =D29/13.1 -> 0.0036277212
A30: 27 | B30: 30 | C30: 0.13542824 | D30: ='leg 2'!C44-'Leg 1'!C44 -> 0.1084375 | E30: =VLOOKUP(B30,Registration!$B$3:$C$77,2,FALSE) -> Mixed | F30: =D30/13.1 -> 0.0082776718
A31: 28 | B31: 31 | C31: 0.1306713 | D31: ='leg 2'!C38-'Leg 1'!C38 -> 0.061018519 | E31: =VLOOKUP(B31,Registration!$B$3:$C$77,2,FALSE) -> Mixed | F31: =D31/13.1 -> 0.0046579022
A32: 29 | B32: 32 | C32: 0.13744213 | D32: ='leg 2'!C47-'Leg 1'!C47 -> 0.087824074 | E32: =VLOOKUP(B32,Registration!$B$3:$C$77,2,FALSE) -> Mixed | F32: =D32/13.1 -> 0.0067041278
A33: 30 | B33: 34 | C33: 0.13002315 | D33: ='leg 2'!C36-'Leg 1'!C36 -> 0.057199074 | E33: =VLOOKUP(B33,Registration!$B$3:$C$77,2,FALSE) -> Mixed | F33: =D33/13.1 -> 0.0043663415
A34: 31 | B34: 35 | C34: 0.12461806 | D34: ='leg 2'!C30-'Leg 1'!C30 -> 0.065729167 | E34: =VLOOKUP(B34,Registration!$B$3:$C$77,2,FALSE) -> Mixed | F34: =D34/13.1 -> 0.0050174936
A35: 32 | B35: 36 | C35: 0.13503472 | D35: ='leg 2'!C43-'Leg 1'!C43 -> 0.070798611 | E35: =VLOOKUP(B35,Registration!$B$3:$C$77,2,FALSE) -> Mixed | F35: =D35/13.1 -> 0.0054044741
A36: 33 | B36: 37 | C36: 0.11680556 | D36: ='leg 2'!C22-'Leg 1'!C22 -> 0.071921296 | E36: =VLOOKUP(B36,Registration!$B$3:$C$77,2,FALSE) -> Mixed | F36: =D36/13.1 -> 0.0054901753
A37: 34 | B37: 38 | C37: 0.12385417 | D37: ='leg 2'!C28-'Leg 1'!C28 -> 0.062395833 | E37: =VLOOKUP(B37,Registration!$B$3:$C$77,2,FALSE) -> Mixed | F37: =D37/13.1 -> 0.0047630407
A38: 35 | B38: 39 | C38: 0.13903935 | D38: ='leg 2'!C50-'Leg 1'!C50 -> 0.050289352 | E38: =VLOOKUP(B38,Registration!$B$3:$C$77,2,FALSE) -> Mixed | F38: =D38/13.1 -> 0.0038388818
A39: 36 | B39: 40 | C39: 0.1606713 | E39: =VLOOKUP(B39,Registration!$B$3:$C$77,2,FALSE) -> Mixed | F39: =D39/13.1 -> 0
A40: 37 | B40: 41 | C40: 0.15630787 | D40: ='leg 2'!C62-'Leg 1'!C62 -> 0.082418981 | E40: =VLOOKUP(B40,Registration!$B$3:$C$77,2,FALSE) -> Mixed | F40: =D40/13.1 -> 0.0062915253
...

Sheet Leg 3
A1: Leg 3 | B1: 2018
F2: 9.6 miles
A3: Place | B3: Bib # | C3: Total Time | D3: Div | E3: Div Place | F3: Pace
A4: 1 | B4: 1 | C4: 0.12983796 | D4: =VLOOKUP(B4,Registration!$B$3:$C$77,2,FALSE) -> Men's | F4: =#REF!/9.6 -> #REF!
A5: 2 | B5: 8 | C5: 0.13148148 | D5: =VLOOKUP(B5,Registration!$B$3:$C$77,2,FALSE) -> Men's | F5: =#REF!/9.6 -> #REF!
A6: 3 | B6: 3 | C6: 0.13800926 | D6: =VLOOKUP(B6,Registration!$B$3:$C$77,2,FALSE) -> Men's | F6: =#REF!/9.6 -> #REF!
A7: 4 | B7: 9 | C7: 0.13905093 | D7: =VLOOKUP(B7,Registration!$B$3:$C$77,2,FALSE) -> Men's | F7: =#REF!/9.6 -> #REF!
A8: 5 | B8: 73 | C8: 0.14378472 | D8: =VLOOKUP(B8,Registration!$B$3:$C$77,2,FALSE) -> HS-Boys | F8: =#REF!/9.6 -> #REF!
A9: 6 | B9: 10 | C9: 1.1965278 | D9: =VLOOKUP(B9,Registration!$B$3:$C$77,2,FALSE) -> Men40+ | F9: =#REF!/9.6 -> #REF!
A10: 7 | B10: 18 | C10: 0.14891204 | D10: =VLOOKUP(B10,Registration!$B$3:$C$77,2,FALSE) -> Mixed | F10: =#REF!/9.6 -> #REF!
A11: 8 | B11: 6 | C11: 0.1502662 | D11: =VLOOKUP(B11,Registration!$B$3:$C$77,2,FALSE) -> Men's | F11: =#REF!/9.6 -> #REF!
A12: 9 | B12: 16 | C12: 0.1575463 | D12: =VLOOKUP(B12,Registration!$B$3:$C$77,2,FALSE) -> Womens | F12: =#REF!/9.6 -> #REF!
A13: 10 | B13: 21 | C13: 0.15990741 | D13: =VLOOKUP(B13,Registration!$B$3:$C$77,2,FALSE) -> Womens | F13: =#REF!/9.6 -> #REF!
A14: 11 | B14: 42 | C14: 0.16041667 | D14: =VLOOKUP(B14,Registration!$B$3:$C$77,2,FALSE) -> Mixed | F14: =#REF!/9.6 -> #REF!
A15: 12 | B15: 70 | C15: 0.161875 | D15: =VLOOKUP(B15,Registration!$B$3:$C$77,2,FALSE) -> HS-Boys | F15: =#REF!/9.6 -> #REF!
... A71: 68 | B71: 53 | C71: 0.25269676 | D71: =VLOOKUP(B71,Registration!$B$3:$C$77,2,FALSE) -> Mixed40+ | F71: =#REF!/9.6 -> #REF!
A72: 69 | D72: =VLOOKUP(B72,Registration!$B$3:$C$77,2,FALSE) -> #N/A | F72: =#REF!/9.6 -> #REF!
A73: 70 | D73: =VLOOKUP(B73,Registration!$B$3:$C$77,2,FALSE) -> #N/A | F73: =#REF!/9.6 -> #REF!
A74: 71 | D74: =VLOOKUP(B74,Registration!$B$3:$C$77,2,FALSE) -> #N/A | F74: =#REF!/9.6 -> #REF!
A75: 72 | D75: =VLOOKUP(B75,Registration!$B$3:$C$77,2,FALSE) -> #N/A | F75: =#REF!/9.6 -> #REF!
A76: 73 | D76: =VLOOKUP(B76,Registration!$B$3:$C$77,2,FALSE) -> #N/A | F76: =#REF!/9.6 -> #REF!
A77: 74 | D77: =VLOOKUP(B77,Registration!$B$3:$C$77,2,FALSE) -> #N/A | F77: =#REF!/9.6 -> #REF!

Sheet Leg 4
A1: Leg 4 | B1: 2017 Tahoe Relay | J1: Leg 4 | K1: 2017 Tahoe Relay
G2: 9.5 miles | O2: 9.5 miles
A3: Place | B3: Bib # | C3: Total Time | D3: Leg Time | E3: Div | F3: Div Place | G3: Pace | J3: Place | K3: Bib # | L3: Total Time | M3: Leg Time | N3: Div | O3: Pace
A4: 1 | B4: 1 | C4: 0.16694444 | D4: =C4-'Leg 3'!C4 -> 0.037106481 | E4: =VLOOKUP(B4,Registration!$B$3:$C$77,2,FALSE) -> Men's | G4: =D4/9.5 -> 0.0039059454 | J4: 1 | K4: 1 | L4: 0.16694444 | M4: =L4-'Leg 3'!K4 -> 0.16694444 | N4: =VLOOKUP(K4,Registration!$B$3:$C$77,2,FALSE) -> Men's | O4: =M4/9.5 -> 0.017573099
A5: 2 | B5: 8 | C5: 0.16864583 | D5: =C5-'Leg 3'!C5 -> 0.037164352 | E5: =VLOOKUP(B5,Registration!$B$3:$C$77,2,FALSE) -> Men's | G5: =D5/9.5 -> 0.003912037 | J5: 3 | K5: 3 | L5: 0.18074074 | M5: =L5-'Leg 3'!K9 -> 0.18074074 | N5: =VLOOKUP(K5,Registration!$B$3:$C$77,2,FALSE) -> Men's | O5: =M5/9.5 -> 0.019025341
A6: 3 | B6: 3 | C6: 0.18074074 | D6: =C6-'Leg 3'!C9 -> -1.015787 | E6: =VLOOKUP(B6,Registration!$B$3:$C$77,2,FALSE) -> Men's | G6: =D6/9.5 -> -0.10692495 | J6: 41 | K6: 4 | L6: 0.25039352 | M6: =L6-'Leg 3'!K47 -> 0.25039352 | N6: =VLOOKUP(K6,Registration!$B$3:$C$77,2,FALSE) -> Men's | O6: =M6/9.5 -> 0.026357212
A7: 4 | B7: 9 | C7: 0.18525463 | D7: =C7-'Leg 3'!C7 -> 0.046203704 | E7: =VLOOKUP(B7,Registration!$B$3:$C$77,2,FALSE) -> Men's | G7: =D7/9.5 -> 0.0048635478 | J7: 61 | K7: 5 | L7: 0.29878472 | M7: =L7-'Leg 3'!K65 -> 0.29878472 | N7: =VLOOKUP(K7,Registration!$B$3:$C$77,2,FALSE) -> Men's | O7: =M7/9.5 -> 0.031451023
A8: 5 | B8: 73 | C8: 0.18550926 | D8: =C8-'Leg 3'!C6 -> 0.0475 | E8: =VLOOKUP(B8,Registration!$B$3:$C$77,2,FALSE) -> HS-Boys | G8: =D8/9.5 -> 0.005 | J8: 8 | K8: 6 | L8: 0.2008912 | M8: =L8-'Leg 3'!K11 -> 0.2008912 | N8: =VLOOKUP(K8,Registration!$B$3:$C$77,2,FALSE) -> Men's | O8: =M8/9.5 -> 0.021146442
A9: 6 | B9: 10 | C9: 0.18888889 | D9: =C9-'Leg 3'!C8 -> 0.045104167 | E9: =VLOOKUP(B9,Registration!$B$3:$C$77,2,FALSE) -> Men40+ | G9: =D9/9.5 -> 0.004747807 | J9: 57 | K9: 7 | L9: 0.28451389 | M9: =L9-'Leg 3'!K62 -> 0.28451389 | N9: =VLOOKUP(K9,Registration!$B$3:$C$77,2,FALSE) -> Men's | O9: =M9/9.5 -> 0.02994883
A10: 7 | B10: 18 | C10: 0.19232639 | D10: =C10-'Leg 3'!C10 -> 0.043414352 | E10: =VLOOKUP(B10,Registration!$B$3:$C$77,2,FALSE) -> Mixed | G10: =D10/9.5 -> 0.0045699318 | J10: 2 | K10: 8 | L10: 0.16864583 | M10: =L10-'Leg 3'!K5 -> 0.16864583 | N10: =VLOOKUP(K10,Registration!$B$3:$C$77,2,FALSE) -> Men's | O10: =M10/9.5 -> 0.017752193
A11: 8 | B11: 6 | C11: 0.2008912 | D11: =C11-'Leg 3'!C11 -> 0.050625 | E11: =VLOOKUP(B11,Registration!$B$3:$C$77,2,FALSE) -> Men's | G11: =D11/9.5 -> 0.0053289474 | J11: 4 | K11: 9 | L11: 0.18525463 | M11: =L11-'Leg 3'!K7 -> 0.18525463 | N11: =VLOOKUP(K11,Registration!$B$3:$C$77,2,FALSE) -> Men's | O11: =M11/9.5 -> 0.019500487
A12: 9 | B12: 16 | C12: 0.20423611 | D12: =C12-'Leg 3'!C12 -> 0.046689815 | E12: =VLOOKUP(B12,Registration!$B$3:$C$77,2,FALSE) -> Womens | G12: =D12/9.5 -> 0.0049147173 | J12: 6 | K12: 10 | L12: 0.18888889 | M12: =L12-'Leg 3'!K8 -> 0.18888889 | N12: =VLOOKUP(K12,Registration!$B$3:$C$77,2,FALSE) -> Men40+ | O12: =M12/9.5 -> 0.019883041
A13: 10 | B13: 50 | C13: 0.20570602 | D13: =C13-'Leg 3'!C16 -> 0.043391204 | E13: =VLOOKUP(B13,Registration!$B$3:$C$77,2,FALSE) -> Mixed | G13: =D13/9.5 -> 0.0045674951 | J13: 28 | K13: 11 | L13: 0.24055556 | M13: =L13-'Leg 3'!K35 -> 0.24055556 | N13: =VLOOKUP(K13,Registration!$B$3:$C$77,2,FALSE) -> Men50+ | O13: =M13/9.5 -> 0.025321637
A14: 11 | B14: 21 | C14: 0.20744213 | D14: =C14-'Leg 3'!C15 -> 0.04556713 | E14: =VLOOKUP(B14,Registration!$B$3:$C$77,2,FALSE) -> Womens | G14: =D14/9.5 -> 0.00479654 | J14: 27 | K14: 12 | L14: 0.23659722 | M14: =L14-'Leg 3'!K40 -> 0.23659722 | N14: =VLOOKUP(K14,Registration!$B$3:$C$77,2,FALSE) -> Men50+ | O14: =M14/9.5 -> 0.024904971
A15: 12 | B15: 70 | C15: 0.2084375 | D15: =C15-'Leg 3'!C13 -> 0.048530093 | E15: =VLOOKUP(B15,Registration!$B$3:$C$77,2,FALSE) -> HS-Boys | G15: =D15/9.5 -> 0.0051084308 | J15: 36 | K15: 13 | L15: 0.24809028 | M15: =L15-'Leg 3'!K37 -> 0.24809028 | N15: =VLOOKUP(K15,Registration!$B$3:$C$77,2,FALSE) -> Ultra | O15: =M15/9.5 -> 0.026114766
A16: 13 | B16: 71 | C16: 0.21184028 | D16: =C16-'Leg 3'!C17 -> 0.048923611 | E16: =VLOOKUP(B16,Registration!$B$3:$C$77,2,FALSE) -> HS-Boys | G16: =D16/9.5 -> 0.0051498538 | J16: 58 | K16: 14 | L16: 0.28643519 | M16: =L16-'Leg 3'!K67 -> 0.28643519 | N16: =VLOOKUP(K16,Registration!$B$3:$C$77,2,FALSE) -> Womens | O16: =M16/9.5 -> 0.030151072
A17: 14 | B17: 37 | C17: 0.21376157 | D17: =C17-'Leg 3'!C14 -> 0.053344907 | E17: =VLOOKUP(B17,Registration!$B$3:$C$77,2,FALSE) -> Mixed | G17: =D17/9.5 -> 0.0056152534 | J17: 9 | K17: 16 | L17: 0.20423611 | M17: =L17-'Leg 3'!K12 -> 0.20423611 | N17: =VLOOKUP(K17,Registration!$B$3:$C$77,2,FALSE) -> Womens | O17: =M17/9.5 -> 0.021498538
A18: 15 | B18: 26 | C18: 0.21434028 | D18: =C18-'Leg 3'!C19 -> 0.046875 | E18: =VLOOKUP(B18,Registration!$B$3:$C$77,2,FALSE) -> Mixed | G18: =D18/9.5 -> 0.0049342105 | J18: 55 | K18: 17 | L18: 0.27707176 | M18: =L18-'Leg 3'!K56 -> 0.27707176 | N18: =VLOOKUP(K18,Registration!$B$3:$C$77,2,FALSE) -> Womens | O18: =M18/9.5 -> 0.029165448
A19: 16 | B19: 69 | C19: 0.21512731 | D19: =C19-'Leg 3'!C20 -> 0.046712963 | E19: =VLOOKUP(B19,Registration!$B$3:$C$77,2,FALSE) -> HS -Boys | G19: =D19/9.5 -> 0.004917154 | J19: 7 | K19: 18 | L19: 0.19232639 | M19: =L19-'Leg 3'!K10 -> 0.19232639 | N19: =VLOOKUP(K19,Registration!$B$3:$C$77,2,FALSE) -> Mixed | O19: =M19/9.5 -> 0.020244883
A20: 17 | B20: 52 | C20: 0.21902778 | D20: =C20-'Leg 3'!C22 -> 0.049456019 | E20: =VLOOKUP(B20,Registration!$B$3:$C$77,2,FALSE) -> Men's | G20: =D20/9.5 -> 0.0052058967 | J20: 31 | K20: 19 | L20: 0.24260417 | M20: =L20-'Leg 3'!K39 -> 0.24260417 | N20: =VLOOKUP(K20,Registration!$B$3:$C$77,2,FALSE) -> Womens | O20: =M20/9.5 -> 0.025537281
A21: 18 | B21: 60 | C21: 0.21905093 | D21: =C21-'Leg 3'!C23 -> 0.049409722 | E21: =VLOOKUP(B21,Registration!$B$3:$C$77,2,FALSE) -> Corp | G21: =D21/9.5 -> 0.0052010234 | J21: 11 | K21: 21 | L21: 0.20744213 | M21: =L21-'Leg 3'!K15 -> 0.20744213 | N21: =VLOOKUP(K21,Registration!$B$3:$C$77,2,FALSE) -> Womens | O21: =M21/9.5 -> 0.021836014
A22: 19 | B22: 55 | C22: 0.22152778 | D22: =C22-'Leg 3'!C21 -> 0.05306713 | E22: =VLOOKUP(B22,Registration!$B$3:$C$77,2,FALSE) -> Mixed40+ | G22: =D22/9.5 -> 0.0055860136 | J22: 21 | K22: 22 | L22: 0.2252662 | M22: =L22-'Leg 3'!K24 -> 0.2252662 | N22: =VLOOKUP(K22,Registration!$B$3:$C$77,2,FALSE) -> Wmn 40+ | O22: =M22/9.5 -> 0.023712232
A23: 20 | B23: 43 | C23: 0.22201389 | D23: =C23-'Leg 3'!C18 -> 0.058252315 | E23: =VLOOKUP(B23,Registration!$B$3:$C$77,2,FALSE) -> Mixed | G23: =D23/9.5 -> 0.0061318226 | J23: 54 | K23: 23 | L23: 0.27050926 | M23: =L23-'Leg 3'!K55 -> 0.27050926 | N23: =VLOOKUP(K23,Registration!$B$3:$C$77,2,FALSE) -> Mixed | O23: =M23/9.5 -> 0.028474659
A24: 21 | B24: 22 | C24: 0.2252662 | D24: =C24-'Leg 3'!C24 -> 0.055474537 | E24: =VLOOKUP(B24,Registration!$B$3:$C$77,2,FALSE) -> Wmn 40+ | G24: =D24/9.5 -> 0.005839425 | J24: 24 | K24: 24 | L24: 0.23138889 | M24: =L24-'Leg 3'!K25 -> 0.23138889 | N24: =VLOOKUP(K24,Registration!$B$3:$C$77,2,FALSE) -> Mixed | O24: =M24/9.5 -> 0.024356725
A25: 22 | B25: 25 | C25: 0.22849537 | D25: =C25-'Leg 3'!C26 -> 0.057592593 | E25: =VLOOKUP(B25,Registration!$B$3:$C$77,2,FALSE) -> Mixed | G25: =D25/9.5 -> 0.0060623782 | J25: 22 | K25: 25 | L25: 0.22849537 | M25: =L25-'Leg 3'!K26 -> 0.22849537 | N25: =VLOOKUP(K25,Registration!$B$3:$C$77,2,FALSE) -> Mixed | O25: =M25/9.5 -> 0.024052144
A26: 23 | B26: 72 | C26: 0.23012731 | D26: =C26-'Leg 3'!C29 -> 0.055532407 | E26: =VLOOKUP(B26,Registration!$B$3:$C$77,2,FALSE) -> HS-Boys | G26: =D26/9.5 -> 0.0058455166 | J26: 15 | K26: 26 | L26: 0.21434028 | M26: =L26-'Leg 3'!K19 -> 0.21434028 | N26: =VLOOKUP(K26,Registration!$B$3:$C$77,2,FALSE) -> Mixed | O26: =M26/9.5 -> 0.022562135
A27: 24 | B27: 24 | C27: 0.23138889 | D27: =C27-'Leg 3'!C25 -> 0.060763889 | E27: =VLOOKUP(B27,Registration!$B$3:$C$77,2,FALSE) -> Mixed | G27: =D27/9.5 -> 0.0063961988 | J27: 47 | K27: 27 | L27: 0.25908565 | M27: =L27-'Leg 3'!K50 -> 0.25908565 | N27: =VLOOKUP(K27,Registration!$B$3:$C$77,2,FALSE) -> Mixed | O27: =M27/9.5 -> 0.027272173
A28: 25 | B28: 63 | C28: 0.23146991 | D28: =C28-'Leg 3'!C27 -> 0.058263889 | E28: =VLOOKUP(B28,Registration!$B$3:$C$77,2,FALSE) -> Corp | G28: =D28/9.5 -> 0.0061330409 | J28: 40 | K28: 28 | L28: 0.25034722 | M28: =L28-'Leg 3'!K52 -> 0.25034722 | N28: =VLOOKUP(K28,Registration!$B$3:$C$77,2,FALSE) -> Mixed | O28: =M28/9.5 -> 0.026352339
A29: 26 | B29: 35 | C29: 0.23408565 | D29: =C29-'Leg 3'!C41 -> 0.042638889 | E29: =VLOOKUP(B29,Registration!$B$3:$C$77,2,FALSE) -> Mixed | G29: =D29/9.5 -> 0.0044883041 | J29: 42 | K29: 29 | L29: 0.25243056 | M29: =L29-'Leg 3'!K33 -> 0.25243056 | N29: =VLOOKUP(K29,Registration!$B$3:$C$77,2,FALSE) -> Mixed | O29: =M29/9.5 -> 0.026571637
A30: 27 | B30: 12 | C30: 0.23659722 | D30: =C30-'Leg 3'!C40 -> 0.046041667 | E30: =VLOOKUP(B30,Registration!$B$3:$C$77,2,FALSE) -> Men50+ | G30: =D30/9.5 -> 0.0048464912 | J30: 38 | K30: 30 | L30: 0.24869213 | M30: =L30-'Leg 3'!K30 -> 0.24869213 | N30: =VLOOKUP(K30,Registration!$B$3:$C$77,2,FALSE) -> Mixed | O30: =M30/9.5 -> 0.026178119
A31: 28 | B31: 11 | C31: 0.24055556 | D31: =C31-'Leg 3'!C35 -> 0.054976852 | E31: =VLOOKUP(B31,Registration!$B$3:$C$77,2,FALSE) -> Men50+ | G31: =D31/9.5 -> 0.005787037 | J31: 29 | K31: 31 | L31: 0.24127315 | M31: =L31-'Leg 3'!K34 -> 0.24127315 | N31: =VLOOKUP(K31,Registration!$B$3:$C$77,2,FALSE) -> Mixed | O31: =M31/9.5 -> 0.025397173
A32: 29 | B32: 31 | C32: 0.24127315 | D32: =C32-'Leg 3'!C34 -> 0.057094907 | E32: =VLOOKUP(B32,Registration!$B$3:$C$77,2,FALSE) -> Mixed | G32: =D32/9.5 -> 0.0060099903 | J32: 45 | K32: 32 | L32: 0.25696759 | M32: =L32-'Leg 3'!K48 -> 0.25696759 | N32: =VLOOKUP(K32,Registration!$B$3:$C$77,2,FALSE) -> Mixed | O32: =M32/9.5 -> 0.02704922
A33: 30 | B33: 36 | C33: 0.24142361 | D33: =C33-'Leg 3'!C32 -> 0.058726852 | E33: =VLOOKUP(B33,Registration!$B$3:$C$77,2,FALSE) -> Mixed | G33: =D33/9.5 -> 0.0061817739 | J33: 34 | K33: 34 | L33: 0.24581019 | M33: =L33-'Leg 3'!K31 -> 0.24581019 | N33: =VLOOKUP(K33,Registration!$B$3:$C$77,2,FALSE) -> Mixed | O33: =M33/9.5 -> 0.025874756
A34: 31 | B34: 19 | C34: 0.24260417 | D34: =C34-'Leg 3'!C39 -> 0.052476852 | E34: =VLOOKUP(B34,Registration!$B$3:$C$77,2,FALSE) -> Womens | G34: =D34/9.5 -> 0.0055238791 | J34: 26 | K34: 35 | L34: 0.23408565 | M34: =L34-'Leg 3'!K41 -> 0.23408565 | N34: =VLOOKUP(K34,Registration!$B$3:$C$77,2,FALSE) -> Mixed | O34: =M34/9.5 -> 0.024640595
A35: 32 | B35: 65 | C35: 0.24392361 | D35: =C35-'Leg 3'!C38 -> 0.05380787 | E35: =VLOOKUP(B35,Registration!$B$3:$C$77,2,FALSE) -> Corp | G35: =D35/9.5 -> 0.0056639864 | J35: 30 | K35: 36 | L35: 0.24142361 | M35: =L35-'Leg 3'!K32 -> 0.24142361 | N35: =VLOOKUP(K35,Registration!$B$3:$C$77,2,FALSE) -> Mixed | O35: =M35/9.5 -> 0.025413012
A36: 33 | B36: 59 | C36: 0.24479167 | D36: =C36-'Leg 3'!C42 -> 0.051365741 | E36: =VLOOKUP(B36,Registration!$B$3:$C$77,2,FALSE) -> Corp | G36: =D36/9.5 -> 0.0054069201 | J36: 14 | K36: 37 | L36: 0.21376157 | M36: =L36-'Leg 3'!K14 -> 0.21376157 | N36: =VLOOKUP(K36,Registration!$B$3:$C$77,2,FALSE) -> Mixed | O36: =M36/9.5 -> 0.022501218
A37: 34 | B37: 34 | C37: 0.24581019 | D37: =C37-'Leg 3'!C31 -> 0.065532407 | E37: =VLOOKUP(B37,Registration!$B$3:$C$77,2,FALSE) -> Mixed | G37: =D37/9.5 -> 0.0068981481 | J37: 39 | K37: 38 | L37: 0.24962963 | M37: =L37-'Leg 3'!K44 -> 0.24962963 | N37: =VLOOKUP(K37,Registration!$B$3:$C$77,2,FALSE) -> Mixed | O37: =M37/9.5 -> 0.026276803
A38: 35 | B38: 62 | C38: 0.24763889 | D38: =C38-'Leg 3'!C36 -> 0.061979167 | E38: =VLOOKUP(B38,Registration!$B$3:$C$77,2,FALSE) -> Corp | G38: =D38/9.5 -> 0.0065241228 | J38: 37 | K38: 39 | L38: 0.24859954 | M38: =L38-'Leg 3'!K45 -> 0.24859954 | N38: =VLOOKUP(K38,Registration!$B$3:$C$77,2,FALSE) -> Mixed | O38: =M38/9.5 -> 0.026168372
A39: 36 | B39: 13 | C39: 0.24809028 | D39: =C39-'Leg 3'!C37 -> 0.059351852 | E39: =VLOOKUP(B39,Registration!$B$3:$C$77,2,FALSE) -> Ultra | G39: =D39/9.5 -> 0.0062475634 | J39: 65 | K39: 40 | L39: 0.30186343 | M39: =L39-'Leg 3'!K63 -> 0.30186343 | N39: =VLOOKUP(K39,Registration!$B$3:$C$77,2,FALSE) -> Mixed | O39: =M39/9.5 -> 0.031775097
A40: 37 | B40: 39 | C40: 0.24859954 | D40: =C40-'Leg 3'!C45 -> 0.052997685 | E40: =VLOOKUP(B40,Registration!$B$3:$C$77,2,FALSE) -> Mixed | G40: =D40/9.5 -> 0.0055787037 | J40: 62 | K40: 41 | L40: 0.29915509 | M40: =L40-'Leg 3'!K68 -> 0.29915509 | N40: =VLOOKUP(K40,Registration!$B$3:$C$77,2,FALSE) -> Mixed | O40: =M40/9.5 -> 0.03149001
...

Sheet Leg 5
A1: Leg 5 | B1: 2018 Tahoe Relay
G2: 10.7 Miles
A3: Place | B3: Bib # | C3: Total Time | D3: Leg Time | E3: Div | F3: Div Place | G3: Pace
A4: 1 | B4: 1 | C4: 0.20850694 | D4: =C4-'Leg 4'!C4 -> 0.0415625 | E4: =VLOOKUP(B4,Registration!$B$3:$C$77,2,FALSE) -> Men's | G4: =D4/10.7 -> 0.0038843458
A5: 2 | B5: 8 | C5: 0.21112269 | D5: =C5-'Leg 4'!C5 -> 0.042476852 | E5: =VLOOKUP(B5,Registration!$B$3:$C$77,2,FALSE) -> Men's | G5: =D5/10.7 -> 0.0039697992
A6: 3 | B6: 3 | C6: 0.22912037 | D6: =C6-'Leg 4'!C7 -> 0.043865741 | E6: =VLOOKUP(B6,Registration!$B$3:$C$77,2,FALSE) -> Men's | G6: =D6/10.7 -> 0.0040996019
A7: 4 | B7: 9 | C7: 0.23431713 | D7: =C7-'Leg 4'!C6 -> 0.053576389 | E7: =VLOOKUP(B7,Registration!$B$3:$C$77,2,FALSE) -> Men's | G7: =D7/10.7 -> 0.0050071391
A8: 5 | B8: 73 | C8: 0.23518519 | D8: =C8-'Leg 4'!C8 -> 0.049675926 | E8: =VLOOKUP(B8,Registration!$B$3:$C$77,2,FALSE) -> HS-Boys | G8: =D8/10.7 -> 0.0046426099
A9: 6 | B9: 10 | C9: 0.23578704 | D9: =C9-'Leg 4'!C9 -> 0.046898148 | E9: =VLOOKUP(B9,Registration!$B$3:$C$77,2,FALSE) -> Men40+ | G9: =D9/10.7 -> 0.0043830045
A10: 7 | B10: 18 | C10: 0.24011574 | D10: =C10-'Leg 4'!C11 -> 0.039224537 | E10: =VLOOKUP(B10,Registration!$B$3:$C$77,2,FALSE) -> Mixed | G10: =D10/10.7 -> 0.0036658446
A11: 8 | B11: 6 | C11: 0.25356481 | D11: =C11-'Leg 4'!C10 -> 0.061238426 | E11: =VLOOKUP(B11,Registration!$B$3:$C$77,2,FALSE) -> Men's | G11: =D11/10.7 -> 0.0057232174
A12: 9 | B12: 16 | C12: 0.25356481 | D12: =C12-'Leg 4'!C12 -> 0.049328704 | E12: =VLOOKUP(B12,Registration!$B$3:$C$77,2,FALSE) -> Womens | G12: =D12/10.7 -> 0.0046101592
A13: 10 | B13: 50 | C13: 0.25892361 | D13: =C13-'Leg 4'!C15 -> 0.050486111 | E13: =VLOOKUP(B13,Registration!$B$3:$C$77,2,FALSE) -> Mixed | G13: =D13/10.7 -> 0.0047183281
A14: 11 | B14: 21 | C14: 0.26197917 | D14: =C14-'Leg 4'!C14 -> 0.054537037 | E14: =VLOOKUP(B14,Registration!$B$3:$C$77,2,FALSE) -> Womens | G14: =D14/10.7 -> 0.0050969193
A15: 12 | B15: 70 | C15: 0.26359954 | D15: =C15-'Leg 4'!C19 -> 0.048472222 | E15: =VLOOKUP(B15,Registration!$B$3:$C$77,2,FALSE) -> HS-Boys | G15: =D15/10.7 -> 0.0045301142
A16: 13 | B16: 69 | C16: 0.26862269 | D16: =C16-'Leg 4'!C16 -> 0.056782407 | E16: =VLOOKUP(B16,Registration!$B$3:$C$77,2,FALSE) -> HS -Boys | G16: =D16/10.7 -> 0.005306767
A17: 14 | B17: 71 | C17: 0.27143519 | D17: =C17-'Leg 4'!C13 -> 0.065729167 | E17: =VLOOKUP(B17,Registration!$B$3:$C$77,2,FALSE) -> HS-Boys | G17: =D17/10.7 -> 0.0061429128
A18: 15 | B18: 37 | C18: 1.3180556 | D18: =C18-'Leg 4'!C17 -> 1.104294 | E18: =VLOOKUP(B18,Registration!$B$3:$C$77,2,FALSE) -> Mixed | G18: =D18/10.7 -> 0.10320504
A19: 16 | B19: 52 | C19: 0.27371528 | D19: =C19-'Leg 4'!C21 -> 0.054664352 | E19: =VLOOKUP(B19,Registration!$B$3:$C$77,2,FALSE) -> Men's | G19: =D19/10.7 -> 0.0051088179
A20: 17 | B20: 26 | C20: 0.27571759 | D20: =C20-'Leg 4'!C20 -> 0.056689815 | E20: =VLOOKUP(B20,Registration!$B$3:$C$77,2,FALSE) -> Mixed | G20: =D20/10.7 -> 0.0052981135
A21: 18 | B21: 55 | C21: 0.2765625 | D21: =C21-'Leg 4'!C18 -> 0.062222222 | E21: =VLOOKUP(B21,Registration!$B$3:$C$77,2,FALSE) -> Mixed40+ | G21: =D21/10.7 -> 0.005815161
A22: 19 | B22: 25 | C22: 0.2840625 | D22: =C22-'Leg 4'!C24 -> 0.058796296 | E22: =VLOOKUP(B22,Registration!$B$3:$C$77,2,FALSE) -> Mixed | G22: =D22/10.7 -> 0.005494981
A23: 20 | B23: 43 | C23: 0.28664352 | D23: =C23-'Leg 4'!C22 -> 0.065115741 | E23: =VLOOKUP(B23,Registration!$B$3:$C$77,2,FALSE) -> Mixed | G23: =D23/10.7 -> 0.0060855832
A24: 21 | B24: 22 | C24: 0.28670139 | D24: =C24-'Leg 4'!C23 -> 0.0646875 | E24: =VLOOKUP(B24,Registration!$B$3:$C$77,2,FALSE) -> Wmn 40+ | G24: =D24/10.7 -> 0.0060455607
A25: 22 | B25: 60 | C25: 0.28923611 | D25: =C25-'Leg 4'!C27 -> 0.057847222 | E25: =VLOOKUP(B25,Registration!$B$3:$C$77,2,FALSE) -> Corp | G25: =D25/10.7 -> 0.0054062825
A26: 23 | B26: 72 | C26: 0.29138889 | D26: =C26-'Leg 4'!C26 -> 0.061261574 | E26: =VLOOKUP(B26,Registration!$B$3:$C$77,2,FALSE) -> HS-Boys | G26: =D26/10.7 -> 0.0057253808
A27: 24 | B27: 24 | C27: 0.29696759 | D27: =C27-'Leg 4'!C25 -> 0.068472222 | E27: =VLOOKUP(B27,Registration!$B$3:$C$77,2,FALSE) -> Mixed | G27: =D27/10.7 -> 0.0063992731
A28: 25 | B28: 12 | C28: 0.29834491 | D28: =C28-'Leg 4'!C28 -> 0.066875 | E28: =VLOOKUP(B28,Registration!$B$3:$C$77,2,FALSE) -> Men50+ | G28: =D28/10.7 -> 0.00625
A29: 26 | B29: 35 | C29: 0.30054398 | D29: =C29-'Leg 4'!C40 -> 0.051944444 | E29: =VLOOKUP(B29,Registration!$B$3:$C$77,2,FALSE) -> Mixed | G29: =D29/10.7 -> 0.004854621
A30: 27 | B30: 11 | C30: 0.30065972 | D30: =C30-'Leg 4'!C30 -> 0.0640625 | E30: =VLOOKUP(B30,Registration!$B$3:$C$77,2,FALSE) -> Men50+ | G30: =D30/10.7 -> 0.0059871495
A31: 28 | B31: 19 | C31: 0.30274306 | D31: =C31-'Leg 4'!C34 -> 0.060138889 | E31: =VLOOKUP(B31,Registration!$B$3:$C$77,2,FALSE) -> Womens | G31: =D31/10.7 -> 0.0056204569
A32: 29 | B32: 31 | C32: 0.30287037 | D32: =C32-'Leg 4'!C37 -> 0.057060185 | E32: =VLOOKUP(B32,Registration!$B$3:$C$77,2,FALSE) -> Mixed | G32: =D32/10.7 -> 0.0053327276
A33: 30 | B33: 36 | C33: 0.303125 | D33: =C33-'Leg 4'!C31 -> 0.062569444 | E33: =VLOOKUP(B33,Registration!$B$3:$C$77,2,FALSE) -> Mixed | G33: =D33/10.7 -> 0.0058476116
A34: 31 | B34: 34 | C34: 0.30585648 | D34: =C34-'Leg 4'!C33 -> 0.06443287 | E34: =VLOOKUP(B34,Registration!$B$3:$C$77,2,FALSE) -> Mixed | G34: =D34/10.7 -> 0.0060217636
A35: 32 | B35: 39 | C35: 0.30733796 | D35: =C35-'Leg 4'!C32 -> 0.066064815 | E35: =VLOOKUP(B35,Registration!$B$3:$C$77,2,FALSE) -> Mixed | G35: =D35/10.7 -> 0.0061742818
A36: 33 | B36: 65 | C36: 0.31119213 | D36: =C36-'Leg 4'!C29 -> 0.077106481 | E36: =VLOOKUP(B36,Registration!$B$3:$C$77,2,FALSE) -> Corp | G36: =D36/10.7 -> 0.0072062132
A37: 34 | B37: 38 | C37: 0.31194444 | D37: =C37-'Leg 4'!C39 -> 0.063854167 | E37: =VLOOKUP(B37,Registration!$B$3:$C$77,2,FALSE) -> Mixed | G37: =D37/10.7 -> 0.0059676791
A38: 35 | B38: 62 | C38: 0.31219907 | D38: =C38-'Leg 4'!C36 -> 0.067407407 | E38: =VLOOKUP(B38,Registration!$B$3:$C$77,2,FALSE) -> Corp | G38: =D38/10.7 -> 0.0062997577
A39: 36 | B39: 30 | C39: 0.31354167 | D39: =C39-'Leg 4'!C35 -> 0.069618056 | E39: =VLOOKUP(B39,Registration!$B$3:$C$77,2,FALSE) -> Mixed | G39: =D39/10.7 -> 0.0065063603
A40: 37 | B40: 63 | C40: 0.31516204 | D40: =C40-'Leg 4'!C41 -> 0.066469907 | E40: =VLOOKUP(B40,Registration!$B$3:$C$77,2,FALSE) -> Corp | G40: =D40/10.7 -> 0.0062121409
...

Sheet Leg 6
A1: Leg 6 | B1: 2018 Tahoe Relay
E2: 8.6 Miles
A3: Place | B3: Bib # | C3: Total Time | D3: Div | E3: Pace
A4: 1 | B4: 1 | C4: 0.24641204 | D4: =VLOOKUP(B4,Registration!$B$3:$C$77,2,FALSE) -> Men's | E4: =#REF!/8.6 -> #REF!
A5: 2 | B5: 3 | C5: 0.26944444 | D5: =VLOOKUP(B5,Registration!$B$3:$C$77,2,FALSE) -> Men's | E5: =#REF!/8.6 -> #REF!
A6: 3 | B6: 4 | C6: 0.38075231 | D6: =VLOOKUP(B6,Registration!$B$3:$C$77,2,FALSE) -> Men's | E6: =#REF!/8.6 -> #REF!
A7: 4 | B7: 5 | C7: 0.41709491 | D7: =VLOOKUP(B7,Registration!$B$3:$C$77,2,FALSE) -> Men's | E7: =#REF!/8.6 -> #REF!
A8: 5 | B8: 6 | C8: 0.30778935 | D8: =VLOOKUP(B8,Registration!$B$3:$C$77,2,FALSE) -> Men's | E8: =#REF!/8.6 -> #REF!
A9: 6 | B9: 7 | C9: 0.40960648 | D9: =VLOOKUP(B9,Registration!$B$3:$C$77,2,FALSE) -> Men's | E9: =#REF!/8.6 -> #REF!
A10: 7 | B10: 8 | C10: 0.25092593 | D10: =VLOOKUP(B10,Registration!$B$3:$C$77,2,FALSE) -> Men's | E10: =#REF!/8.6 -> #REF!
A11: 8 | B11: 9 | C11: 0.27340278 | D11: =VLOOKUP(B11,Registration!$B$3:$C$77,2,FALSE) -> Men's | E11: =#REF!/8.6 -> #REF!
A12: 9 | B12: 10 | C12: 0.27435185 | D12: =VLOOKUP(B12,Registration!$B$3:$C$77,2,FALSE) -> Men40+ | E12: =#REF!/8.6 -> #REF!
A13: 10 | B13: 11 | C13: 0.35335648 | D13: =VLOOKUP(B13,Registration!$B$3:$C$77,2,FALSE) -> Men50+ | E13: =#REF!/8.6 -> #REF!
A14: 11 | B14: 12 | C14: 0.34597222 | D14: =VLOOKUP(B14,Registration!$B$3:$C$77,2,FALSE) -> Men50+ | E14: =#REF!/8.6 -> #REF!
A15: 12 | B15: 13 | C15: 0.39461806 | D15: =VLOOKUP(B15,Registration!$B$3:$C$77,2,FALSE) -> Ultra | E15: =#REF!/8.6 -> #REF!
... A70: 67 | B70: 73 | C70: 0.2796875 | D70: =VLOOKUP(B70,Registration!$B$3:$C$77,2,FALSE) -> HS-Boys | E70: =#REF!/8.6 -> #REF!

Sheet Leg 7
A1: Leg 7 | B1: 2018
F2: 10.5 Miles
A3: Place | B3: Bib # | C3: Total Time | D3: Div | E3: Div Place | F3: Pace
A4: 1 | B4: 1 | C4: 0.2856713 | D4: =VLOOKUP(B4,Registration!$B$3:$C$77,2,FALSE) -> Men's | F4: =#REF!/11.1 -> #REF!
A5: 2 | B5: 8 | C5: 0.28831019 | D5: =VLOOKUP(B5,Registration!$B$3:$C$77,2,FALSE) -> Men's | F5: =#REF!/11.1 -> #REF!
A6: 3 | B6: 3 | C6: 0.31226852 | D6: =VLOOKUP(B6,Registration!$B$3:$C$77,2,FALSE) -> Men's | F6: =#REF!/11.1 -> #REF!
A7: 4 | B7: 9 | C7: 0.31905093 | D7: =VLOOKUP(B7,Registration!$B$3:$C$77,2,FALSE) -> Men's | F7: =#REF!/11.1 -> #REF!
A8: 5 | B8: 10 | C8: 0.31982639 | D8: =VLOOKUP(B8,Registration!$B$3:$C$77,2,FALSE) -> Men40+ | F8: =#REF!/11.1 -> #REF!
A9: 6 | B9: 73 | C9: 0.32894676 | D9: =VLOOKUP(B9,Registration!$B$3:$C$77,2,FALSE) -> HS-Boys | F9: =#REF!/11.1 -> #REF!
A10: 7 | B10: 18 | C10: 0.33082176 | D10: =VLOOKUP(B10,Registration!$B$3:$C$77,2,FALSE) -> Mixed | F10: =#REF!/11.1 -> #REF!
A11: 8 | B11: 16 | C11: 0.35038194 | D11: =VLOOKUP(B11,Registration!$B$3:$C$77,2,FALSE) -> Womens | F11: =#REF!/11.1 -> #REF!
A12: 9 | B12: 50 | C12: 0.35268519 | D12: =VLOOKUP(B12,Registration!$B$3:$C$77,2,FALSE) -> Mixed | F12: =#REF!/11.1 -> #REF!
A13: 10 | B13: 6 | C13: 0.35607639 | D13: =VLOOKUP(B13,Registration!$B$3:$C$77,2,FALSE) -> Men's | F13: =#REF!/11.1 -> #REF!
A14: 11 | B14: 70 | C14: 0.36019676 | D14: =VLOOKUP(B14,Registration!$B$3:$C$77,2,FALSE) -> HS-Boys | F14: =#REF!/11.1 -> #REF!
A15: 12 | B15: 69 | C15: 0.36115741 | D15: =VLOOKUP(B15,Registration!$B$3:$C$77,2,FALSE) -> HS -Boys | F15: =#REF!/11.1 -> #REF!
... A69: 66 | B69: 53 | C69: 0.54516204 | D69: =VLOOKUP(B69,Registration!$B$3:$C$77,2,FALSE) -> Mixed40+ | F69: =#REF!/11.1 -> #REF!
A70: 67 | D70: =VLOOKUP(B70,Registration!$B$3:$C$77,2,FALSE) -> #N/A | F70: =#REF!/11.1 -> #REF!
A71: 68 | D71: =VLOOKUP(B71,Registration!$B$3:$C$77,2,FALSE) -> #N/A | F71: =#REF!/11.1 -> #REF!
A72: 69 | D72: =VLOOKUP(B72,Registration!$B$3:$C$77,2,FALSE) -> #N/A | F72: =#REF!/11.1 -> #REF!
A73: 70 | D73: =VLOOKUP(B73,Registration!$B$3:$C$77,2,FALSE) -> #N/A | F73: =#REF!/11.1 -> #REF!
A74: 71 | D74: =VLOOKUP(B74,Registration!$B$3:$C$77,2,FALSE) -> #N/A | F74: =#REF!/11.1 -> #REF!
A75: 72 | D75: =VLOOKUP(B75,Registration!$B$3:$C$77,2,FALSE) -> #N/A | F75: =#REF!/11.1 -> #REF!
A76: 73 | D76: =VLOOKUP(B76,Registration!$B$3:$C$77,2,FALSE) -> #N/A | F76: =#REF!/11.1 -> #REF!
A77: 74 | D77: =VLOOKUP(B77,Registration!$B$3:$C$77,2,FALSE) -> #N/A | F77: =#REF!/11.1 -> #REF!
